NAMESPACE            LAST SEEN   TYPE      REASON                    OBJECT                                                   MESSAGE
default              111s        Normal    Starting                  node/kubeaquarium-control-plane
kube-system          2m4s        Normal    Pulled                    pod/etcd-kubeaquarium-control-plane                      Container image "registry.k8s.io/etcd:3.6.8-0" already present on machine and can be accessed by the pod
default              2m4s        Normal    NodeHasSufficientMemory   node/kubeaquarium-control-plane                          Node kubeaquarium-control-plane status is now: NodeHasSufficientMemory
kube-system          2m4s        Normal    Pulled                    pod/kube-scheduler-kubeaquarium-control-plane            Container image "registry.k8s.io/kube-scheduler:v1.36.1" already present on machine and can be accessed by the pod
default              2m4s        Warning   SystemOOM                 node/kubeaquarium-control-plane                          System OOM encountered, victim process: nginx, pid: 2180419
default              2m4s        Warning   SystemOOM                 node/kubeaquarium-control-plane                          System OOM encountered, victim process: coredns, pid: 2179822
kube-system          2m4s        Normal    Pulled                    pod/kube-controller-manager-kubeaquarium-control-plane   Container image "registry.k8s.io/kube-controller-manager:v1.36.1" already present on machine and can be accessed by the pod
default              2m4s        Warning   SystemOOM                 node/kubeaquarium-control-plane                          System OOM encountered, victim process: local-path-prov, pid: 2184010
default              2m4s        Normal    NodeHasSufficientPID      node/kubeaquarium-control-plane                          Node kubeaquarium-control-plane status is now: NodeHasSufficientPID
kube-system          2m4s        Normal    Pulled                    pod/kube-apiserver-kubeaquarium-control-plane            Container image "registry.k8s.io/kube-apiserver:v1.36.1" already present on machine and can be accessed by the pod
default              2m4s        Warning   SystemOOM                 node/kubeaquarium-control-plane                          System OOM encountered, victim process: coredns, pid: 2179856
default              2m4s        Warning   SystemOOM                 node/kubeaquarium-control-plane                          System OOM encountered, victim process: sh, pid: 2180189
default              2m4s        Normal    NodeHasNoDiskPressure     node/kubeaquarium-control-plane                          Node kubeaquarium-control-plane status is now: NodeHasNoDiskPressure
default              2m4s        Warning   SystemOOM                 node/kubeaquarium-control-plane                          System OOM encountered, victim process: sh, pid: 2180454
default              2m4s        Normal    NodeAllocatableEnforced   node/kubeaquarium-control-plane                          Updated Node Allocatable limit across pods
default              2m4s        Normal    Starting                  node/kubeaquarium-control-plane                          Starting kubelet.
default              2m4s        Warning   SystemOOM                 node/kubeaquarium-control-plane                          System OOM encountered, victim process: sh, pid: 2180493
kube-system          2m3s        Normal    Started                   pod/kube-apiserver-kubeaquarium-control-plane            Container started
kube-system          2m3s        Normal    Started                   pod/kube-scheduler-kubeaquarium-control-plane            Container started
kube-system          2m3s        Normal    Created                   pod/etcd-kubeaquarium-control-plane                      Container created
kube-system          2m3s        Normal    Created                   pod/kube-scheduler-kubeaquarium-control-plane            Container created
kube-system          2m3s        Normal    Started                   pod/etcd-kubeaquarium-control-plane                      Container started
kube-system          2m3s        Normal    Created                   pod/kube-apiserver-kubeaquarium-control-plane            Container created
kube-system          2m3s        Normal    Created                   pod/kube-controller-manager-kubeaquarium-control-plane   Container created
kube-system          2m3s        Normal    Started                   pod/kube-controller-manager-kubeaquarium-control-plane   Container started
kube-system          119s        Normal    LeaderElection            lease/kube-controller-manager                            kubeaquarium-control-plane_8ba5306b-14a4-41e8-9c48-8d16f8bdbbd3 became leader
default              119s        Warning   SystemOOM                 node/kubeaquarium-control-plane                          System OOM encountered, victim process: coredns, pid: 2179856
default              119s        Warning   SystemOOM                 node/kubeaquarium-control-plane                          System OOM encountered, victim process: nginx, pid: 2180419
default              119s        Warning   SystemOOM                 node/kubeaquarium-control-plane                          System OOM encountered, victim process: local-path-prov, pid: 2184010
default              119s        Normal    NodeAllocatableEnforced   node/kubeaquarium-control-plane                          Updated Node Allocatable limit across pods
default              119s        Normal    NodeHasSufficientMemory   node/kubeaquarium-control-plane                          Node kubeaquarium-control-plane status is now: NodeHasSufficientMemory
default              119s        Normal    NodeHasSufficientPID      node/kubeaquarium-control-plane                          Node kubeaquarium-control-plane status is now: NodeHasSufficientPID
default              119s        Warning   SystemOOM                 node/kubeaquarium-control-plane                          System OOM encountered, victim process: coredns, pid: 2179822
default              119s        Normal    NodeHasNoDiskPressure     node/kubeaquarium-control-plane                          Node kubeaquarium-control-plane status is now: NodeHasNoDiskPressure
default              119s        Normal    Starting                  node/kubeaquarium-control-plane                          Starting kubelet.
default              119s        Warning   SystemOOM                 node/kubeaquarium-control-plane                          System OOM encountered, victim process: sh, pid: 2180493
default              119s        Warning   SystemOOM                 node/kubeaquarium-control-plane                          System OOM encountered, victim process: sh, pid: 2180454
default              119s        Warning   SystemOOM                 node/kubeaquarium-control-plane                          System OOM encountered, victim process: sh, pid: 2180189
kube-system          118s        Warning   Unhealthy                 pod/kube-scheduler-kubeaquarium-control-plane            Readiness probe failed: HTTP probe failed with statuscode: 500
kube-system          117s        Normal    LeaderElection            lease/kube-scheduler                                     kubeaquarium-control-plane_b33634d3-b031-40ef-9af4-58d7992de0dd became leader
local-path-storage   113s        Normal    ScalingReplicaSet         deployment/local-path-provisioner                        Scaled up replica set local-path-provisioner-855c7b7774 from 0 to 1
default              113s        Normal    RegisteredNode            node/kubeaquarium-control-plane                          Node kubeaquarium-control-plane event: Registered Node kubeaquarium-control-plane in Controller
kube-system          113s        Normal    ScalingReplicaSet         deployment/coredns                                       Scaled up replica set coredns-589f44dc88 from 0 to 2
kube-system          112s        Normal    SuccessfulCreate          replicaset/coredns-589f44dc88                            Created pod: coredns-589f44dc88-jj2q6
kube-system          112s        Normal    Pulled                    pod/kindnet-2fwln                                        Container image "docker.io/kindest/kindnetd:v20260528-9350166c" already present on machine and can be accessed by the pod
kube-system          112s        Normal    Scheduled                 pod/kube-proxy-cn6ks                                     Successfully assigned kube-system/kube-proxy-cn6ks to kubeaquarium-control-plane
kube-system          112s        Normal    Pulled                    pod/kube-proxy-cn6ks                                     Container image "registry.k8s.io/kube-proxy:v1.36.1" already present on machine and can be accessed by the pod
kube-system          112s        Warning   FailedScheduling          pod/coredns-589f44dc88-xgtqt                             0/1 nodes are available: 1 node(s) had untolerated taint(s). no new claims to deallocate, preemption: 0/1 nodes are available: 1 Preemption is not helpful for scheduling.
local-path-storage   112s        Normal    SuccessfulCreate          replicaset/local-path-provisioner-855c7b7774             Created pod: local-path-provisioner-855c7b7774-trv54
kube-system          112s        Normal    SuccessfulCreate          daemonset/kube-proxy                                     Created pod: kube-proxy-cn6ks
kube-system          112s        Normal    SuccessfulCreate          daemonset/kindnet                                        Created pod: kindnet-2fwln
local-path-storage   112s        Warning   FailedScheduling          pod/local-path-provisioner-855c7b7774-trv54              0/1 nodes are available: 1 node(s) had untolerated taint(s). no new claims to deallocate, preemption: 0/1 nodes are available: 1 Preemption is not helpful for scheduling.
kube-system          112s        Normal    SuccessfulCreate          replicaset/coredns-589f44dc88                            Created pod: coredns-589f44dc88-xgtqt
kube-system          112s        Warning   FailedScheduling          pod/coredns-589f44dc88-jj2q6                             0/1 nodes are available: 1 node(s) had untolerated taint(s). no new claims to deallocate, preemption: 0/1 nodes are available: 1 Preemption is not helpful for scheduling.
kube-system          112s        Normal    Scheduled                 pod/kindnet-2fwln                                        Successfully assigned kube-system/kindnet-2fwln to kubeaquarium-control-plane
kube-system          111s        Normal    Created                   pod/kindnet-2fwln                                        Container created
kube-system          111s        Normal    Started                   pod/kindnet-2fwln                                        Container started
kube-system          111s        Normal    Started                   pod/kube-proxy-cn6ks                                     Container started
kube-system          111s        Normal    Created                   pod/kube-proxy-cn6ks                                     Container created
local-path-storage   101s        Normal    Scheduled                 pod/local-path-provisioner-855c7b7774-trv54              Successfully assigned local-path-storage/local-path-provisioner-855c7b7774-trv54 to kubeaquarium-control-plane
web                  101s        Normal    Scheduled                 pod/nginx-5d9bc6447-t8srr                                Successfully assigned web/nginx-5d9bc6447-t8srr to kubeaquarium-control-plane
payments             101s        Normal    ScalingReplicaSet         deployment/crashloop                                     Scaled up replica set crashloop-ccf4f7c64 from 0 to 1
default              101s        Normal    NodeReady                 node/kubeaquarium-control-plane                          Node kubeaquarium-control-plane status is now: NodeReady
monitoring           101s        Normal    ScalingReplicaSet         deployment/grafana-fake                                  Scaled up replica set grafana-fake-66d5775fc9 from 0 to 2
kube-system          101s        Normal    Scheduled                 pod/coredns-589f44dc88-jj2q6                             Successfully assigned kube-system/coredns-589f44dc88-jj2q6 to kubeaquarium-control-plane
payments             101s        Warning   FailedScheduling          pod/redis-69b984c64-n2knp                                0/1 nodes are available: 1 Insufficient cpu. no new claims to deallocate, preemption: 0/1 nodes are available: 1 No preemption victims found for incoming pod.
web                  101s        Normal    SuccessfulCreate          replicaset/httpbin-76dbdc6fcc                            Created pod: httpbin-76dbdc6fcc-pmrj2
payments             101s        Normal    Scheduled                 pod/redis-69b984c64-nf56x                                Successfully assigned payments/redis-69b984c64-nf56x to kubeaquarium-control-plane
payments             101s        Normal    SuccessfulCreate          replicaset/worker-5cb55b5c8                              Created pod: worker-5cb55b5c8-57cj2
web                  101s        Normal    Scheduled                 pod/nginx-5d9bc6447-z2cnz                                Successfully assigned web/nginx-5d9bc6447-z2cnz to kubeaquarium-control-plane
monitoring           101s        Normal    SuccessfulCreate          replicaset/grafana-fake-66d5775fc9                       Created pod: grafana-fake-66d5775fc9-lrg6r
payments             101s        Warning   FailedScheduling          pod/redis-69b984c64-qgt5n                                0/1 nodes are available: 1 Insufficient cpu. no new claims to deallocate, preemption: 0/1 nodes are available: 1 No preemption victims found for incoming pod.
payments             101s        Normal    SuccessfulCreate          replicaset/redis-69b984c64                               Created pod: redis-69b984c64-nf56x
payments             101s        Normal    SuccessfulCreate          replicaset/redis-69b984c64                               Created pod: redis-69b984c64-n2knp
payments             101s        Normal    SuccessfulCreate          replicaset/worker-5cb55b5c8                              Created pod: worker-5cb55b5c8-dqjbl
payments             101s        Normal    SuccessfulCreate          replicaset/worker-5cb55b5c8                              Created pod: worker-5cb55b5c8-j2mkj
kube-system          101s        Normal    Scheduled                 pod/coredns-589f44dc88-xgtqt                             Successfully assigned kube-system/coredns-589f44dc88-xgtqt to kubeaquarium-control-plane
payments             101s        Normal    SuccessfulCreate          replicaset/redis-69b984c64                               Created pod: redis-69b984c64-qgt5n
payments             101s        Normal    SuccessfulCreate          replicaset/worker-5cb55b5c8                              Created pod: worker-5cb55b5c8-fhtwp
payments             101s        Normal    Scheduled                 pod/worker-5cb55b5c8-frzgh                               Successfully assigned payments/worker-5cb55b5c8-frzgh to kubeaquarium-control-plane
monitoring           101s        Normal    SuccessfulCreate          replicaset/grafana-fake-66d5775fc9                       Created pod: grafana-fake-66d5775fc9-xpjwt
payments             101s        Normal    ScalingReplicaSet         deployment/redis                                         Scaled up replica set redis-69b984c64 from 0 to 3
web                  101s        Normal    SuccessfulCreate          replicaset/nginx-5d9bc6447                               Created pod: nginx-5d9bc6447-h8jv2
web                  101s        Normal    SuccessfulCreate          replicaset/nginx-5d9bc6447                               Created pod: nginx-5d9bc6447-t8srr
payments             101s        Normal    ScalingReplicaSet         deployment/worker                                        Scaled up replica set worker-5cb55b5c8 from 0 to 5
payments             101s        Normal    SuccessfulCreate          replicaset/worker-5cb55b5c8                              Created pod: worker-5cb55b5c8-frzgh
web                  101s        Normal    Scheduled                 pod/httpbin-76dbdc6fcc-lpf84                             Successfully assigned web/httpbin-76dbdc6fcc-lpf84 to kubeaquarium-control-plane
web                  101s        Normal    Scheduled                 pod/nginx-5d9bc6447-h8jv2                                Successfully assigned web/nginx-5d9bc6447-h8jv2 to kubeaquarium-control-plane
monitoring           101s        Normal    SuccessfulCreate          replicaset/prometheus-fake-7ccfb864b6                    Created pod: prometheus-fake-7ccfb864b6-45sp2
monitoring           101s        Normal    ScalingReplicaSet         deployment/prometheus-fake                               Scaled up replica set prometheus-fake-7ccfb864b6 from 0 to 1
web                  101s        Normal    SuccessfulCreate          replicaset/nginx-5d9bc6447                               Created pod: nginx-5d9bc6447-z2cnz
web                  101s        Normal    SuccessfulCreate          replicaset/nginx-5d9bc6447                               Created pod: nginx-5d9bc6447-86vs8
payments             101s        Normal    Scheduled                 pod/worker-5cb55b5c8-57cj2                               Successfully assigned payments/worker-5cb55b5c8-57cj2 to kubeaquarium-control-plane
web                  101s        Normal    Scheduled                 pod/nginx-5d9bc6447-86vs8                                Successfully assigned web/nginx-5d9bc6447-86vs8 to kubeaquarium-control-plane
web                  101s        Normal    Scheduled                 pod/httpbin-76dbdc6fcc-pmrj2                             Successfully assigned web/httpbin-76dbdc6fcc-pmrj2 to kubeaquarium-control-plane
monitoring           101s        Normal    Scheduled                 pod/grafana-fake-66d5775fc9-lrg6r                        Successfully assigned monitoring/grafana-fake-66d5775fc9-lrg6r to kubeaquarium-control-plane
web                  101s        Normal    ScalingReplicaSet         deployment/httpbin                                       Scaled up replica set httpbin-76dbdc6fcc from 0 to 2
payments             101s        Normal    Scheduled                 pod/worker-5cb55b5c8-j2mkj                               Successfully assigned payments/worker-5cb55b5c8-j2mkj to kubeaquarium-control-plane
payments             101s        Normal    Scheduled                 pod/worker-5cb55b5c8-dqjbl                               Successfully assigned payments/worker-5cb55b5c8-dqjbl to kubeaquarium-control-plane
web                  101s        Normal    SuccessfulCreate          replicaset/httpbin-76dbdc6fcc                            Created pod: httpbin-76dbdc6fcc-lpf84
web                  101s        Normal    ScalingReplicaSet         deployment/nginx                                         Scaled up replica set nginx-5d9bc6447 from 0 to 4
web                  100s        Warning   FailedScheduling          pod/pending-pod-dcbb776d5-xds4z                          0/1 nodes are available: 1 node(s) didn't match Pod's node affinity/selector. no new claims to deallocate, preemption: 0/1 nodes are available: 1 Preemption is not helpful for scheduling.
bench-payments       100s        Normal    Scheduled                 pod/api-sleeper-7467d44dc4-tgfms                         Successfully assigned bench-payments/api-sleeper-7467d44dc4-tgfms to kubeaquarium-control-plane
bench-payments       100s        Normal    Scheduled                 pod/ledger-0                                             Successfully assigned bench-payments/ledger-0 to kubeaquarium-control-plane
web                  100s        Normal    Pulling                   pod/nginx-5d9bc6447-z2cnz                                Pulling image "nginx:1.27-alpine"
bench-payments       100s        Normal    ScalingReplicaSet         deployment/api-sleeper                                   Scaled up replica set api-sleeper-7467d44dc4 from 0 to 1
web                  100s        Normal    Pulling                   pod/nginx-5d9bc6447-h8jv2                                Pulling image "nginx:1.27-alpine"
web                  100s        Normal    Pulling                   pod/nginx-5d9bc6447-86vs8                                Pulling image "nginx:1.27-alpine"
payments             100s        Normal    Scheduled                 pod/crashloop-ccf4f7c64-4mgwp                            Successfully assigned payments/crashloop-ccf4f7c64-4mgwp to kubeaquarium-control-plane
bench-payments       100s        Normal    SuccessfulCreate          replicaset/api-sleeper-7467d44dc4                        Created pod: api-sleeper-7467d44dc4-tgfms
bench-web            100s        Normal    SuccessfulCreate          replicaset/web-sleeper-7b48cbb58f                        Created pod: web-sleeper-7b48cbb58f-nk5fp
web                  100s        Normal    Pulling                   pod/httpbin-76dbdc6fcc-pmrj2                             Pulling image "kennethreitz/httpbin"
payments             100s        Normal    Scheduled                 pod/worker-5cb55b5c8-fhtwp                               Successfully assigned payments/worker-5cb55b5c8-fhtwp to kubeaquarium-control-plane
web                  100s        Normal    Pulling                   pod/httpbin-76dbdc6fcc-lpf84                             Pulling image "kennethreitz/httpbin"
web                  100s        Normal    SuccessfulCreate          replicaset/pending-pod-dcbb776d5                         Created pod: pending-pod-dcbb776d5-xds4z
bench-payments       100s        Normal    SuccessfulCreate          statefulset/ledger                                       Create Pod ledger-0 in StatefulSet ledger successful
local-path-storage   100s        Normal    Pulled                    pod/local-path-provisioner-855c7b7774-trv54              Container image "docker.io/kindest/local-path-provisioner:v20260521-9fb22683" already present on machine and can be accessed by the pod
bench-platform       100s        Normal    Scheduled                 pod/completed-report-m7vl2                               Successfully assigned bench-platform/completed-report-m7vl2 to kubeaquarium-control-plane
payments             100s        Normal    SuccessfulCreate          replicaset/crashloop-ccf4f7c64                           Created pod: crashloop-ccf4f7c64-4mgwp
bench-platform       100s        Normal    SuccessfulCreate          job/completed-report                                     Created pod: completed-report-m7vl2
bench-platform       100s        Normal    Scheduled                 pod/node-agent-v84fg                                     Successfully assigned bench-platform/node-agent-v84fg to kubeaquarium-control-plane
bench-platform       100s        Normal    SuccessfulCreate          daemonset/node-agent                                     Created pod: node-agent-v84fg
web                  100s        Normal    Pulling                   pod/nginx-5d9bc6447-t8srr                                Pulling image "nginx:1.27-alpine"
bench-web            100s        Normal    ScalingReplicaSet         deployment/web-sleeper                                   Scaled up replica set web-sleeper-7b48cbb58f from 0 to 1
bench-web            100s        Normal    Scheduled                 pod/web-sleeper-7b48cbb58f-nk5fp                         Successfully assigned bench-web/web-sleeper-7b48cbb58f-nk5fp to kubeaquarium-control-plane
kube-system          100s        Normal    Pulled                    pod/coredns-589f44dc88-jj2q6                             Container image "registry.k8s.io/coredns/coredns:v1.14.2" already present on machine and can be accessed by the pod
kube-system          100s        Normal    Pulled                    pod/coredns-589f44dc88-xgtqt                             Container image "registry.k8s.io/coredns/coredns:v1.14.2" already present on machine and can be accessed by the pod
bench-noisy          100s        Normal    ScalingReplicaSet         deployment/crashloop                                     Scaled up replica set crashloop-db7bf9c6b from 0 to 2
web                  100s        Normal    ScalingReplicaSet         deployment/pending-pod                                   Scaled up replica set pending-pod-dcbb776d5 from 0 to 1
bench-payments       99s         Normal    Scheduled                 pod/api-sleeper-7467d44dc4-q64zv                         Successfully assigned bench-payments/api-sleeper-7467d44dc4-q64zv to kubeaquarium-control-plane
bench-noisy          99s         Normal    SuccessfulCreate          replicaset/pending-7f97f7646f                            Created pod: pending-7f97f7646f-r9p4l
bench-noisy          99s         Normal    SuccessfulCreate          replicaset/pending-7f97f7646f                            Created pod: pending-7f97f7646f-wpnd8
bench-noisy          99s         Warning   FailedScheduling          pod/pending-7f97f7646f-wpnd8                             0/1 nodes are available: 1 node(s) didn't match Pod's node affinity/selector. no new claims to deallocate, preemption: 0/1 nodes are available: 1 Preemption is not helpful for scheduling.
bench-noisy          99s         Warning   FailedScheduling          pod/pending-7f97f7646f-r9p4l                             0/1 nodes are available: 1 node(s) didn't match Pod's node affinity/selector. no new claims to deallocate, preemption: 0/1 nodes are available: 1 Preemption is not helpful for scheduling.
bench-noisy          99s         Normal    ScalingReplicaSet         deployment/crashloop                                     Scaled up replica set crashloop-db7bf9c6b from 2 to 33
payments             99s         Normal    Pulling                   pod/redis-69b984c64-nf56x                                Pulling image "redis:7-alpine"
bench-noisy          99s         Normal    ScalingReplicaSet         deployment/pending                                       Scaled up replica set pending-7f97f7646f from 0 to 2
bench-noisy          99s         Normal    Scheduled                 pod/crashloop-db7bf9c6b-92c2b                            Successfully assigned bench-noisy/crashloop-db7bf9c6b-92c2b to kubeaquarium-control-plane
payments             99s         Normal    Pulling                   pod/worker-5cb55b5c8-57cj2                               Pulling image "busybox:1.36"
payments             99s         Normal    Pulling                   pod/worker-5cb55b5c8-j2mkj                               Pulling image "busybox:1.36"
bench-noisy          99s         Normal    SuccessfulCreate          replicaset/crashloop-db7bf9c6b                           Created pod: crashloop-db7bf9c6b-cdnxz
payments             99s         Normal    Pulling                   pod/worker-5cb55b5c8-dqjbl                               Pulling image "busybox:1.36"
payments             99s         Normal    Pulling                   pod/worker-5cb55b5c8-frzgh                               Pulling image "busybox:1.36"
bench-noisy          99s         Normal    SuccessfulCreate          replicaset/crashloop-db7bf9c6b                           Created pod: crashloop-db7bf9c6b-92c2b
bench-web            99s         Normal    SuccessfulCreate          replicaset/web-sleeper-7b48cbb58f                        Created pod: web-sleeper-7b48cbb58f-4tfjw
payments             99s         Normal    Pulling                   pod/worker-5cb55b5c8-fhtwp                               Pulling image "busybox:1.36"
payments             99s         Normal    Pulling                   pod/crashloop-ccf4f7c64-4mgwp                            Pulling image "busybox:1.36"
monitoring           99s         Normal    Pulling                   pod/grafana-fake-66d5775fc9-lrg6r                        Pulling image "nginx:1.27-alpine"
bench-payments       99s         Normal    Scheduled                 pod/api-sleeper-7467d44dc4-qbl8h                         Successfully assigned bench-payments/api-sleeper-7467d44dc4-qbl8h to kubeaquarium-control-plane
bench-payments       99s         Normal    SuccessfulCreate          replicaset/api-sleeper-7467d44dc4                        Created pod: api-sleeper-7467d44dc4-qbl8h
bench-payments       99s         Normal    SuccessfulCreate          replicaset/api-sleeper-7467d44dc4                        Created pod: api-sleeper-7467d44dc4-q64zv
bench-web            99s         Normal    ScalingReplicaSet         deployment/web-sleeper                                   Scaled up replica set web-sleeper-7b48cbb58f from 1 to 77
bench-payments       99s         Normal    SuccessfulCreate          replicaset/api-sleeper-7467d44dc4                        Created pod: api-sleeper-7467d44dc4-tkxtc
bench-payments       99s         Normal    ScalingReplicaSet         deployment/api-sleeper                                   Scaled up replica set api-sleeper-7467d44dc4 from 1 to 77
bench-noisy          99s         Normal    Scheduled                 pod/crashloop-db7bf9c6b-cdnxz                            Successfully assigned bench-noisy/crashloop-db7bf9c6b-cdnxz to kubeaquarium-control-plane
bench-payments       98s         Normal    Scheduled                 pod/api-sleeper-7467d44dc4-4g9p9                         Successfully assigned bench-payments/api-sleeper-7467d44dc4-4g9p9 to kubeaquarium-control-plane
bench-payments       98s         Normal    Scheduled                 pod/api-sleeper-7467d44dc4-sh25x                         Successfully assigned bench-payments/api-sleeper-7467d44dc4-sh25x to kubeaquarium-control-plane
bench-platform       98s         Normal    Pulling                   pod/node-agent-v84fg                                     Pulling image "busybox:1.36"
bench-payments       98s         Normal    Pulling                   pod/ledger-0                                             Pulling image "busybox:1.36"
bench-web            98s         Normal    Scheduled                 pod/web-sleeper-7b48cbb58f-t74g5                         Successfully assigned bench-web/web-sleeper-7b48cbb58f-t74g5 to kubeaquarium-control-plane
bench-payments       98s         Normal    Scheduled                 pod/api-sleeper-7467d44dc4-lhzwk                         Successfully assigned bench-payments/api-sleeper-7467d44dc4-lhzwk to kubeaquarium-control-plane
bench-web            98s         Normal    Scheduled                 pod/web-sleeper-7b48cbb58f-4tfjw                         Successfully assigned bench-web/web-sleeper-7b48cbb58f-4tfjw to kubeaquarium-control-plane
bench-payments       98s         Normal    Scheduled                 pod/api-sleeper-7467d44dc4-kmvv5                         Successfully assigned bench-payments/api-sleeper-7467d44dc4-kmvv5 to kubeaquarium-control-plane
bench-payments       98s         Normal    Scheduled                 pod/api-sleeper-7467d44dc4-84z92                         Successfully assigned bench-payments/api-sleeper-7467d44dc4-84z92 to kubeaquarium-control-plane
bench-payments       98s         Normal    Scheduled                 pod/api-sleeper-7467d44dc4-4bdkj                         Successfully assigned bench-payments/api-sleeper-7467d44dc4-4bdkj to kubeaquarium-control-plane
bench-noisy          98s         Normal    SuccessfulCreate          replicaset/crashloop-db7bf9c6b                           Created pod: crashloop-db7bf9c6b-pkg9l
bench-web            98s         Normal    SuccessfulCreate          replicaset/web-sleeper-7b48cbb58f                        Created pod: web-sleeper-7b48cbb58f-t74g5
bench-web            98s         Normal    SuccessfulCreate          replicaset/web-sleeper-7b48cbb58f                        Created pod: web-sleeper-7b48cbb58f-grls6
bench-payments       98s         Normal    Scheduled                 pod/api-sleeper-7467d44dc4-lps4c                         Successfully assigned bench-payments/api-sleeper-7467d44dc4-lps4c to kubeaquarium-control-plane
bench-web            98s         Normal    SuccessfulCreate          replicaset/web-sleeper-7b48cbb58f                        Created pod: web-sleeper-7b48cbb58f-brhpm
bench-payments       98s         Normal    Scheduled                 pod/api-sleeper-7467d44dc4-rgqsk                         Successfully assigned bench-payments/api-sleeper-7467d44dc4-rgqsk to kubeaquarium-control-plane
bench-payments       98s         Normal    SuccessfulCreate          replicaset/api-sleeper-7467d44dc4                        Created pod: api-sleeper-7467d44dc4-sh25x
bench-web            98s         Normal    SuccessfulCreate          replicaset/web-sleeper-7b48cbb58f                        Created pod: web-sleeper-7b48cbb58f-8cwzz
bench-web            98s         Normal    SuccessfulCreate          replicaset/web-sleeper-7b48cbb58f                        Created pod: web-sleeper-7b48cbb58f-fjd2n
bench-web            98s         Normal    SuccessfulCreate          replicaset/web-sleeper-7b48cbb58f                        Created pod: web-sleeper-7b48cbb58f-5r9x9
bench-payments       98s         Normal    SuccessfulCreate          replicaset/api-sleeper-7467d44dc4                        Created pod: api-sleeper-7467d44dc4-55pvq
bench-payments       98s         Normal    Scheduled                 pod/api-sleeper-7467d44dc4-vfzr4                         Successfully assigned bench-payments/api-sleeper-7467d44dc4-vfzr4 to kubeaquarium-control-plane
bench-payments       98s         Normal    SuccessfulCreate          replicaset/api-sleeper-7467d44dc4                        Created pod: api-sleeper-7467d44dc4-vfzr4
bench-web            98s         Normal    Scheduled                 pod/web-sleeper-7b48cbb58f-grls6                         Successfully assigned bench-web/web-sleeper-7b48cbb58f-grls6 to kubeaquarium-control-plane
bench-payments       98s         Normal    SuccessfulCreate          replicaset/api-sleeper-7467d44dc4                        Created pod: api-sleeper-7467d44dc4-lhzwk
bench-noisy          98s         Normal    Pulling                   pod/crashloop-db7bf9c6b-92c2b                            Pulling image "busybox:1.36"
bench-payments       98s         Normal    SuccessfulCreate          replicaset/api-sleeper-7467d44dc4                        Created pod: api-sleeper-7467d44dc4-4g9p9
bench-web            98s         Normal    Scheduled                 pod/web-sleeper-7b48cbb58f-brhpm                         Successfully assigned bench-web/web-sleeper-7b48cbb58f-brhpm to kubeaquarium-control-plane
bench-payments       98s         Normal    Scheduled                 pod/api-sleeper-7467d44dc4-4ds98                         Successfully assigned bench-payments/api-sleeper-7467d44dc4-4ds98 to kubeaquarium-control-plane
bench-payments       98s         Normal    Scheduled                 pod/api-sleeper-7467d44dc4-tkxtc                         Successfully assigned bench-payments/api-sleeper-7467d44dc4-tkxtc to kubeaquarium-control-plane
bench-platform       98s         Normal    Pulling                   pod/completed-report-m7vl2                               Pulling image "busybox:1.36"
bench-payments       98s         Normal    Scheduled                 pod/api-sleeper-7467d44dc4-55pvq                         Successfully assigned bench-payments/api-sleeper-7467d44dc4-55pvq to kubeaquarium-control-plane
bench-payments       98s         Normal    Scheduled                 pod/api-sleeper-7467d44dc4-cxhtk                         Successfully assigned bench-payments/api-sleeper-7467d44dc4-cxhtk to kubeaquarium-control-plane
bench-noisy          98s         Normal    Scheduled                 pod/crashloop-db7bf9c6b-pkg9l                            Successfully assigned bench-noisy/crashloop-db7bf9c6b-pkg9l to kubeaquarium-control-plane
bench-payments       97s         Normal    Pulling                   pod/api-sleeper-7467d44dc4-tgfms                         Pulling image "busybox:1.36"
bench-web            97s         Normal    Pulling                   pod/web-sleeper-7b48cbb58f-nk5fp                         Pulling image "busybox:1.36"
bench-noisy          97s         Normal    Pulling                   pod/crashloop-db7bf9c6b-cdnxz                            Pulling image "busybox:1.36"
bench-noisy          97s         Normal    SuccessfulCreate          replicaset/crashloop-db7bf9c6b                           Created pod: crashloop-db7bf9c6b-8fjsm
bench-payments       97s         Normal    Pulling                   pod/api-sleeper-7467d44dc4-qbl8h                         Pulling image "busybox:1.36"
bench-noisy          97s         Normal    SuccessfulCreate          replicaset/crashloop-db7bf9c6b                           Created pod: crashloop-db7bf9c6b-8kntx
bench-noisy          97s         Normal    Scheduled                 pod/crashloop-db7bf9c6b-8kntx                            Successfully assigned bench-noisy/crashloop-db7bf9c6b-8kntx to kubeaquarium-control-plane
bench-payments       97s         Normal    Pulling                   pod/api-sleeper-7467d44dc4-q64zv                         Pulling image "busybox:1.36"
kube-system          96s         Normal    Created                   pod/coredns-589f44dc88-xgtqt                             Container created
bench-web            96s         Normal    Pulling                   pod/web-sleeper-7b48cbb58f-4tfjw                         Pulling image "busybox:1.36"
bench-payments       96s         Normal    Pulling                   pod/api-sleeper-7467d44dc4-kmvv5                         Pulling image "busybox:1.36"
bench-web            96s         Normal    Pulling                   pod/web-sleeper-7b48cbb58f-t74g5                         Pulling image "busybox:1.36"
bench-web            96s         Normal    Pulling                   pod/web-sleeper-7b48cbb58f-grls6                         Pulling image "busybox:1.36"
bench-payments       96s         Normal    Pulling                   pod/api-sleeper-7467d44dc4-lhzwk                         Pulling image "busybox:1.36"
bench-payments       96s         Normal    Pulling                   pod/api-sleeper-7467d44dc4-4bdkj                         Pulling image "busybox:1.36"
bench-payments       96s         Normal    Pulling                   pod/api-sleeper-7467d44dc4-tkxtc                         Pulling image "busybox:1.36"
bench-payments       96s         Normal    Pulling                   pod/api-sleeper-7467d44dc4-vfzr4                         Pulling image "busybox:1.36"
local-path-storage   96s         Normal    Created                   pod/local-path-provisioner-855c7b7774-trv54              Container created
bench-payments       96s         Normal    Pulling                   pod/api-sleeper-7467d44dc4-cxhtk                         Pulling image "busybox:1.36"
kube-system          96s         Normal    Started                   pod/coredns-589f44dc88-xgtqt                             Container started
bench-noisy          96s         Normal    Pulling                   pod/crashloop-db7bf9c6b-pkg9l                            Pulling image "busybox:1.36"
bench-payments       96s         Normal    Pulling                   pod/api-sleeper-7467d44dc4-84z92                         Pulling image "busybox:1.36"
kube-system          96s         Normal    Created                   pod/coredns-589f44dc88-jj2q6                             Container created
bench-payments       96s         Normal    Pulling                   pod/api-sleeper-7467d44dc4-lps4c                         Pulling image "busybox:1.36"
bench-noisy          96s         Normal    SuccessfulCreate          replicaset/crashloop-db7bf9c6b                           Created pod: crashloop-db7bf9c6b-5vtkn
bench-web            96s         Normal    Pulling                   pod/web-sleeper-7b48cbb58f-brhpm                         Pulling image "busybox:1.36"
local-path-storage   96s         Normal    Started                   pod/local-path-provisioner-855c7b7774-trv54              Container started
bench-noisy          96s         Normal    SuccessfulCreate          replicaset/crashloop-db7bf9c6b                           Created pod: crashloop-db7bf9c6b-b95z8
bench-noisy          96s         Normal    SuccessfulCreate          replicaset/crashloop-db7bf9c6b                           Created pod: crashloop-db7bf9c6b-r9277
bench-noisy          96s         Normal    SuccessfulCreate          replicaset/crashloop-db7bf9c6b                           Created pod: crashloop-db7bf9c6b-q4gn9
bench-payments       96s         Normal    Pulling                   pod/api-sleeper-7467d44dc4-4g9p9                         Pulling image "busybox:1.36"
bench-payments       96s         Normal    Pulling                   pod/api-sleeper-7467d44dc4-4ds98                         Pulling image "busybox:1.36"
bench-payments       96s         Normal    Pulling                   pod/api-sleeper-7467d44dc4-sh25x                         Pulling image "busybox:1.36"
bench-web            96s         Normal    SuccessfulCreate          replicaset/web-sleeper-7b48cbb58f                        Created pod: web-sleeper-7b48cbb58f-tqszq
bench-payments       96s         Normal    Pulling                   pod/api-sleeper-7467d44dc4-rgqsk                         Pulling image "busybox:1.36"
bench-noisy          96s         Normal    Pulling                   pod/crashloop-db7bf9c6b-8kntx                            Pulling image "busybox:1.36"
kube-system          95s         Warning   Unhealthy                 pod/coredns-589f44dc88-jj2q6                             Readiness probe failed: Get "http://10.244.0.2:8181/ready": dial tcp 10.244.0.2:8181: connect: connection refused
kube-system          95s         Warning   Unhealthy                 pod/coredns-589f44dc88-xgtqt                             Readiness probe failed: Get "http://10.244.0.4:8181/ready": dial tcp 10.244.0.4:8181: connect: connection refused
kube-system          95s         Normal    Started                   pod/coredns-589f44dc88-jj2q6                             Container started
bench-payments       93s         Normal    Pulling                   pod/api-sleeper-7467d44dc4-55pvq                         Pulling image "busybox:1.36"
web                  92s         Normal    Started                   pod/nginx-5d9bc6447-z2cnz                                Container started
web                  92s         Normal    Created                   pod/nginx-5d9bc6447-z2cnz                                Container created
web                  92s         Normal    Pulled                    pod/nginx-5d9bc6447-z2cnz                                Successfully pulled image "nginx:1.27-alpine" in 8.205s (8.205s including waiting). Image size: 21832241 bytes.
web                  91s         Normal    Pulled                    pod/nginx-5d9bc6447-h8jv2                                Successfully pulled image "nginx:1.27-alpine" in 741ms (8.928s including waiting). Image size: 21832241 bytes.
web                  91s         Normal    Started                   pod/nginx-5d9bc6447-h8jv2                                Container started
web                  91s         Normal    Created                   pod/nginx-5d9bc6447-h8jv2                                Container created
web                  90s         Normal    Started                   pod/nginx-5d9bc6447-t8srr                                Container started
web                  90s         Normal    Created                   pod/nginx-5d9bc6447-t8srr                                Container created
web                  90s         Normal    Pulled                    pod/nginx-5d9bc6447-t8srr                                Successfully pulled image "nginx:1.27-alpine" in 752ms (9.618s including waiting). Image size: 21832241 bytes.
bench-payments       87s         Normal    SuccessfulCreate          replicaset/api-sleeper-7467d44dc4                        (combined from similar events): Created pod: api-sleeper-7467d44dc4-lmrwm
bench-web            86s         Normal    SuccessfulCreate          replicaset/web-sleeper-7b48cbb58f                        (combined from similar events): Created pod: web-sleeper-7b48cbb58f-p5mdr
bench-noisy          85s         Normal    SuccessfulCreate          replicaset/crashloop-db7bf9c6b                           (combined from similar events): Created pod: crashloop-db7bf9c6b-gdkc8
web                  83s         Normal    Started                   pod/httpbin-76dbdc6fcc-pmrj2                             Container started
web                  83s         Normal    Created                   pod/httpbin-76dbdc6fcc-pmrj2                             Container created
web                  83s         Normal    Pulled                    pod/httpbin-76dbdc6fcc-pmrj2                             Successfully pulled image "kennethreitz/httpbin" in 7.333s (16.878s including waiting). Image size: 214174220 bytes.
web                  82s         Normal    Pulled                    pod/httpbin-76dbdc6fcc-lpf84                             Successfully pulled image "kennethreitz/httpbin" in 731ms (17.544s including waiting). Image size: 214174220 bytes.
web                  82s         Normal    Started                   pod/httpbin-76dbdc6fcc-lpf84                             Container started
web                  82s         Normal    Created                   pod/httpbin-76dbdc6fcc-lpf84                             Container created
monitoring           81s         Normal    Started                   pod/grafana-fake-66d5775fc9-lrg6r                        Container started
web                  81s         Normal    Started                   pod/nginx-5d9bc6447-86vs8                                Container started
web                  81s         Normal    Created                   pod/nginx-5d9bc6447-86vs8                                Container created
web                  81s         Normal    Pulled                    pod/nginx-5d9bc6447-86vs8                                Successfully pulled image "nginx:1.27-alpine" in 739ms (18.232s including waiting). Image size: 21832241 bytes.
monitoring           81s         Normal    Pulled                    pod/grafana-fake-66d5775fc9-lrg6r                        Successfully pulled image "nginx:1.27-alpine" in 729ms (18.029s including waiting). Image size: 21832241 bytes.
monitoring           81s         Normal    Created                   pod/grafana-fake-66d5775fc9-lrg6r                        Container created
payments             78s         Normal    Pulled                    pod/redis-69b984c64-nf56x                                Successfully pulled image "redis:7-alpine" in 2.975s (20.992s including waiting). Image size: 16790804 bytes.
payments             78s         Normal    Created                   pod/redis-69b984c64-nf56x                                Container created
payments             78s         Normal    Started                   pod/redis-69b984c64-nf56x                                Container started
payments             75s         Normal    Pulled                    pod/worker-5cb55b5c8-fhtwp                               Successfully pulled image "busybox:1.36" in 2.371s (23.338s including waiting). Image size: 1906887 bytes.
payments             75s         Normal    Pulled                    pod/crashloop-ccf4f7c64-4mgwp                            Successfully pulled image "busybox:1.36" in 765ms (24.104s including waiting). Image size: 1906887 bytes.
payments             75s         Normal    Started                   pod/worker-5cb55b5c8-fhtwp                               Container started
payments             75s         Normal    Created                   pod/worker-5cb55b5c8-fhtwp                               Container created
payments             74s         Normal    Started                   pod/worker-5cb55b5c8-frzgh                               Container started
payments             74s         Normal    Created                   pod/worker-5cb55b5c8-frzgh                               Container created
payments             74s         Normal    Pulled                    pod/worker-5cb55b5c8-frzgh                               Successfully pulled image "busybox:1.36" in 712ms (24.816s including waiting). Image size: 1906887 bytes.
payments             73s         Normal    Started                   pod/worker-5cb55b5c8-j2mkj                               Container started
payments             73s         Normal    Created                   pod/worker-5cb55b5c8-j2mkj                               Container created
payments             73s         Normal    Pulled                    pod/worker-5cb55b5c8-j2mkj                               Successfully pulled image "busybox:1.36" in 810ms (25.624s including waiting). Image size: 1906887 bytes.
payments             72s         Normal    Created                   pod/worker-5cb55b5c8-dqjbl                               Container created
payments             72s         Normal    Pulled                    pod/worker-5cb55b5c8-dqjbl                               Successfully pulled image "busybox:1.36" in 759ms (26.978s including waiting). Image size: 1906887 bytes.
payments             72s         Normal    Started                   pod/worker-5cb55b5c8-57cj2                               Container started
payments             72s         Normal    Created                   pod/worker-5cb55b5c8-57cj2                               Container created
payments             72s         Normal    Pulled                    pod/worker-5cb55b5c8-57cj2                               Successfully pulled image "busybox:1.36" in 708ms (26.285s including waiting). Image size: 1906887 bytes.
payments             71s         Normal    Started                   pod/worker-5cb55b5c8-dqjbl                               Container started
bench-platform       71s         Normal    Pulled                    pod/completed-report-m7vl2                               Successfully pulled image "busybox:1.36" in 758ms (27.228s including waiting). Image size: 1906887 bytes.
bench-platform       71s         Normal    Created                   pod/completed-report-m7vl2                               Container created
bench-platform       71s         Normal    Started                   pod/completed-report-m7vl2                               Container started
bench-payments       70s         Normal    Pulled                    pod/ledger-0                                             Successfully pulled image "busybox:1.36" in 997ms (27.815s including waiting). Image size: 1906887 bytes.
bench-payments       70s         Normal    Created                   pod/ledger-0                                             Container created
bench-platform       69s         Normal    Pulled                    pod/node-agent-v84fg                                     Successfully pulled image "busybox:1.36" in 735ms (28.512s including waiting). Image size: 1906887 bytes.
bench-payments       69s         Normal    Started                   pod/ledger-0                                             Container started
bench-platform       69s         Normal    Created                   pod/node-agent-v84fg                                     Container created
bench-payments       69s         Normal    SuccessfulCreate          statefulset/ledger                                       Create Pod ledger-1 in StatefulSet ledger successful
bench-noisy          68s         Normal    Pulled                    pod/crashloop-db7bf9c6b-92c2b                            Successfully pulled image "busybox:1.36" in 764ms (29.259s including waiting). Image size: 1906887 bytes.
bench-platform       68s         Normal    Started                   pod/node-agent-v84fg                                     Container started
bench-platform       68s         Normal    Completed                 job/completed-report                                     Job completed
bench-noisy          68s         Normal    Pulled                    pod/crashloop-db7bf9c6b-cdnxz                            Successfully pulled image "busybox:1.36" in 756ms (29.757s including waiting). Image size: 1906887 bytes.
bench-web            67s         Normal    Pulled                    pod/web-sleeper-7b48cbb58f-nk5fp                         Successfully pulled image "busybox:1.36" in 732ms (30.46s including waiting). Image size: 1906887 bytes.
bench-web            67s         Normal    Created                   pod/web-sleeper-7b48cbb58f-nk5fp                         Container created
bench-web            66s         Normal    Started                   pod/web-sleeper-7b48cbb58f-nk5fp                         Container started
bench-payments       66s         Normal    Pulled                    pod/api-sleeper-7467d44dc4-tgfms                         Successfully pulled image "busybox:1.36" in 735ms (31.144s including waiting). Image size: 1906887 bytes.
bench-payments       66s         Normal    Created                   pod/api-sleeper-7467d44dc4-tgfms                         Container created
bench-payments       65s         Normal    Created                   pod/api-sleeper-7467d44dc4-q64zv                         Container created
bench-payments       65s         Normal    Started                   pod/api-sleeper-7467d44dc4-tgfms                         Container started
bench-payments       65s         Normal    Pulled                    pod/api-sleeper-7467d44dc4-qbl8h                         Successfully pulled image "busybox:1.36" in 744ms (32.068s including waiting). Image size: 1906887 bytes.
bench-payments       65s         Normal    Pulled                    pod/api-sleeper-7467d44dc4-q64zv                         Successfully pulled image "busybox:1.36" in 749ms (31.336s including waiting). Image size: 1906887 bytes.
bench-payments       65s         Normal    Created                   pod/api-sleeper-7467d44dc4-qbl8h                         Container created
bench-payments       64s         Normal    Started                   pod/api-sleeper-7467d44dc4-q64zv                         Container started
bench-web            64s         Normal    Pulled                    pod/web-sleeper-7b48cbb58f-4tfjw                         Successfully pulled image "busybox:1.36" in 747ms (32.534s including waiting). Image size: 1906887 bytes.
bench-payments       64s         Normal    Started                   pod/api-sleeper-7467d44dc4-qbl8h                         Container started
bench-web            64s         Normal    Created                   pod/web-sleeper-7b48cbb58f-4tfjw                         Container created
bench-web            63s         Normal    Started                   pod/web-sleeper-7b48cbb58f-4tfjw                         Container started
bench-payments       63s         Normal    Pulled                    pod/api-sleeper-7467d44dc4-4g9p9                         Successfully pulled image "busybox:1.36" in 702ms (33.085s including waiting). Image size: 1906887 bytes.
bench-payments       63s         Normal    Created                   pod/api-sleeper-7467d44dc4-4g9p9                         Container created
bench-payments       62s         Normal    Pulled                    pod/api-sleeper-7467d44dc4-lhzwk                         Successfully pulled image "busybox:1.36" in 734ms (33.784s including waiting). Image size: 1906887 bytes.
bench-payments       62s         Normal    Created                   pod/api-sleeper-7467d44dc4-lhzwk                         Container created
bench-noisy          62s         Normal    Pulled                    pod/crashloop-db7bf9c6b-pkg9l                            Successfully pulled image "busybox:1.36" in 726ms (34.501s including waiting). Image size: 1906887 bytes.
bench-payments       62s         Normal    Started                   pod/api-sleeper-7467d44dc4-lhzwk                         Container started
bench-payments       62s         Normal    Started                   pod/api-sleeper-7467d44dc4-4g9p9                         Container started
bench-web            61s         Normal    Pulled                    pod/web-sleeper-7b48cbb58f-grls6                         Successfully pulled image "busybox:1.36" in 738ms (35.236s including waiting). Image size: 1906887 bytes.
bench-web            61s         Normal    Created                   pod/web-sleeper-7b48cbb58f-grls6                         Container created
bench-payments       60s         Normal    Created                   pod/api-sleeper-7467d44dc4-tkxtc                         Container created
bench-payments       60s         Normal    Pulled                    pod/api-sleeper-7467d44dc4-tkxtc                         Successfully pulled image "busybox:1.36" in 729ms (35.875s including waiting). Image size: 1906887 bytes.
bench-web            60s         Normal    Started                   pod/web-sleeper-7b48cbb58f-grls6                         Container started
bench-noisy          59s         Normal    Pulled                    pod/crashloop-db7bf9c6b-8kntx                            Successfully pulled image "busybox:1.36" in 742ms (37.195s including waiting). Image size: 1906887 bytes.
bench-web            59s         Normal    Started                   pod/web-sleeper-7b48cbb58f-t74g5                         Container started
bench-payments       59s         Normal    Started                   pod/api-sleeper-7467d44dc4-tkxtc                         Container started
bench-web            59s         Normal    Created                   pod/web-sleeper-7b48cbb58f-t74g5                         Container created
bench-web            59s         Normal    Pulled                    pod/web-sleeper-7b48cbb58f-t74g5                         Successfully pulled image "busybox:1.36" in 767ms (36.636s including waiting). Image size: 1906887 bytes.
bench-payments       58s         Normal    Pulled                    pod/api-sleeper-7467d44dc4-vfzr4                         Successfully pulled image "busybox:1.36" in 706ms (37.889s including waiting). Image size: 1906887 bytes.
bench-payments       58s         Normal    Created                   pod/api-sleeper-7467d44dc4-vfzr4                         Container created
bench-payments       57s         Normal    Started                   pod/api-sleeper-7467d44dc4-vfzr4                         Container started
bench-payments       57s         Normal    Pulled                    pod/api-sleeper-7467d44dc4-4bdkj                         Successfully pulled image "busybox:1.36" in 719ms (39.25s including waiting). Image size: 1906887 bytes.
bench-payments       57s         Normal    Created                   pod/api-sleeper-7467d44dc4-4bdkj                         Container created
bench-payments       57s         Normal    Started                   pod/api-sleeper-7467d44dc4-sh25x                         Container started
bench-payments       57s         Normal    Created                   pod/api-sleeper-7467d44dc4-sh25x                         Container created
bench-payments       57s         Normal    Pulled                    pod/api-sleeper-7467d44dc4-sh25x                         Successfully pulled image "busybox:1.36" in 739ms (38.604s including waiting). Image size: 1906887 bytes.
bench-payments       56s         Normal    Started                   pod/api-sleeper-7467d44dc4-4bdkj                         Container started
bench-payments       56s         Normal    Created                   pod/api-sleeper-7467d44dc4-rgqsk                         Container created
bench-payments       56s         Normal    Pulled                    pod/api-sleeper-7467d44dc4-rgqsk                         Successfully pulled image "busybox:1.36" in 716ms (39.964s including waiting). Image size: 1906887 bytes.
bench-platform       55s         Normal    Created                   pod/scheduled-report-29715585-jb2w7                      Container created
bench-platform       55s         Normal    Started                   pod/scheduled-report-29715585-jb2w7                      Container started
bench-platform       55s         Normal    SuccessfulCreate          cronjob/scheduled-report                                 Created job scheduled-report-29715585
bench-payments       55s         Normal    Started                   pod/api-sleeper-7467d44dc4-rgqsk                         Container started
bench-platform       55s         Normal    Scheduled                 pod/scheduled-report-29715585-jb2w7                      Successfully assigned bench-platform/scheduled-report-29715585-jb2w7 to kubeaquarium-control-plane
bench-platform       55s         Normal    SuccessfulCreate          job/scheduled-report-29715585                            Created pod: scheduled-report-29715585-jb2w7
bench-web            55s         Normal    Pulled                    pod/web-sleeper-7b48cbb58f-brhpm                         Successfully pulled image "busybox:1.36" in 716ms (40.579s including waiting). Image size: 1906887 bytes.
bench-platform       55s         Normal    Pulled                    pod/scheduled-report-29715585-jb2w7                      Container image "busybox:1.36" already present on machine and can be accessed by the pod
bench-web            55s         Normal    Created                   pod/web-sleeper-7b48cbb58f-brhpm                         Container created
bench-web            55s         Normal    Started                   pod/web-sleeper-7b48cbb58f-brhpm                         Container started
bench-payments       54s         Normal    Created                   pod/api-sleeper-7467d44dc4-84z92                         Container created
bench-payments       54s         Normal    Pulled                    pod/api-sleeper-7467d44dc4-4ds98                         Successfully pulled image "busybox:1.36" in 731ms (42.021s including waiting). Image size: 1906887 bytes.
bench-payments       54s         Normal    Started                   pod/api-sleeper-7467d44dc4-84z92                         Container started
bench-payments       54s         Normal    Pulled                    pod/api-sleeper-7467d44dc4-84z92                         Successfully pulled image "busybox:1.36" in 750ms (41.316s including waiting). Image size: 1906887 bytes.
bench-payments       54s         Normal    Created                   pod/api-sleeper-7467d44dc4-4ds98                         Container created
bench-web            53s         Warning   FailedScheduling          pod/web-sleeper-7b48cbb58f-669f5                         0/1 nodes are available: 1 Insufficient cpu. no new claims to deallocate, preemption: 0/1 nodes are available: 1 No preemption victims found for incoming pod.
monitoring           53s         Warning   FailedScheduling          pod/grafana-fake-66d5775fc9-xpjwt                        0/1 nodes are available: 1 Insufficient cpu, 1 Insufficient memory. no new claims to deallocate, preemption: 0/1 nodes are available: 1 No preemption victims found for incoming pod.
bench-web            53s         Warning   FailedScheduling          pod/web-sleeper-7b48cbb58f-tqszq                         0/1 nodes are available: 1 Insufficient cpu. no new claims to deallocate, preemption: 0/1 nodes are available: 1 No preemption victims found for incoming pod.
bench-web            53s         Warning   FailedScheduling          pod/web-sleeper-7b48cbb58f-vcjnw                         0/1 nodes are available: 1 Insufficient cpu. no new claims to deallocate, preemption: 0/1 nodes are available: 1 No preemption victims found for incoming pod.
bench-web            53s         Warning   FailedScheduling          pod/web-sleeper-7b48cbb58f-vgh2m                         0/1 nodes are available: 1 Insufficient cpu. no new claims to deallocate, preemption: 0/1 nodes are available: 1 No preemption victims found for incoming pod.
bench-web            53s         Warning   FailedScheduling          pod/web-sleeper-7b48cbb58f-wm7xp                         0/1 nodes are available: 1 Insufficient cpu. no new claims to deallocate, preemption: 0/1 nodes are available: 1 No preemption victims found for incoming pod.
bench-web            53s         Warning   FailedScheduling          pod/web-sleeper-7b48cbb58f-wqngs                         0/1 nodes are available: 1 Insufficient cpu. no new claims to deallocate, preemption: 0/1 nodes are available: 1 No preemption victims found for incoming pod.
bench-web            53s         Warning   FailedScheduling          pod/web-sleeper-7b48cbb58f-wwbvg                         0/1 nodes are available: 1 Insufficient cpu. no new claims to deallocate, preemption: 0/1 nodes are available: 1 No preemption victims found for incoming pod.
bench-web            53s         Warning   FailedScheduling          pod/web-sleeper-7b48cbb58f-xftsb                         0/1 nodes are available: 1 Insufficient cpu. no new claims to deallocate, preemption: 0/1 nodes are available: 1 No preemption victims found for incoming pod.
bench-web            53s         Warning   FailedScheduling          pod/web-sleeper-7b48cbb58f-xmv2q                         0/1 nodes are available: 1 Insufficient cpu. no new claims to deallocate, preemption: 0/1 nodes are available: 1 No preemption victims found for incoming pod.
bench-web            53s         Warning   FailedScheduling          pod/web-sleeper-7b48cbb58f-scttl                         0/1 nodes are available: 1 Insufficient cpu. no new claims to deallocate, preemption: 0/1 nodes are available: 1 No preemption victims found for incoming pod.
bench-web            53s         Warning   FailedScheduling          pod/web-sleeper-7b48cbb58f-s29ph                         0/1 nodes are available: 1 Insufficient cpu. no new claims to deallocate, preemption: 0/1 nodes are available: 1 No preemption victims found for incoming pod.
bench-web            53s         Warning   FailedScheduling          pod/web-sleeper-7b48cbb58f-rhgw7                         0/1 nodes are available: 1 Insufficient cpu. no new claims to deallocate, preemption: 0/1 nodes are available: 1 No preemption victims found for incoming pod.
bench-web            53s         Warning   FailedScheduling          pod/web-sleeper-7b48cbb58f-rh2hq                         0/1 nodes are available: 1 Insufficient cpu. no new claims to deallocate, preemption: 0/1 nodes are available: 1 No preemption victims found for incoming pod.
bench-web            53s         Warning   FailedScheduling          pod/web-sleeper-7b48cbb58f-rddqr                         0/1 nodes are available: 1 Insufficient cpu. no new claims to deallocate, preemption: 0/1 nodes are available: 1 No preemption victims found for incoming pod.
bench-web            53s         Warning   FailedScheduling          pod/web-sleeper-7b48cbb58f-qvjkh                         0/1 nodes are available: 1 Insufficient cpu. no new claims to deallocate, preemption: 0/1 nodes are available: 1 No preemption victims found for incoming pod.
bench-web            53s         Warning   FailedScheduling          pod/web-sleeper-7b48cbb58f-qqcg6                         0/1 nodes are available: 1 Insufficient cpu. no new claims to deallocate, preemption: 0/1 nodes are available: 1 No preemption victims found for incoming pod.
bench-web            53s         Warning   FailedScheduling          pod/web-sleeper-7b48cbb58f-qhwvd                         0/1 nodes are available: 1 Insufficient cpu. no new claims to deallocate, preemption: 0/1 nodes are available: 1 No preemption victims found for incoming pod.
bench-web            53s         Warning   FailedScheduling          pod/web-sleeper-7b48cbb58f-p5mdr                         0/1 nodes are available: 1 Insufficient cpu. no new claims to deallocate, preemption: 0/1 nodes are available: 1 No preemption victims found for incoming pod.
bench-web            53s         Warning   FailedScheduling          pod/web-sleeper-7b48cbb58f-nfdgh                         0/1 nodes are available: 1 Insufficient cpu. no new claims to deallocate, preemption: 0/1 nodes are available: 1 No preemption victims found for incoming pod.
bench-web            53s         Warning   FailedScheduling          pod/web-sleeper-7b48cbb58f-ndlvx                         0/1 nodes are available: 1 Insufficient cpu. no new claims to deallocate, preemption: 0/1 nodes are available: 1 No preemption victims found for incoming pod.
bench-web            53s         Warning   FailedScheduling          pod/web-sleeper-7b48cbb58f-n8zvh                         0/1 nodes are available: 1 Insufficient cpu. no new claims to deallocate, preemption: 0/1 nodes are available: 1 No preemption victims found for incoming pod.
bench-web            53s         Warning   FailedScheduling          pod/web-sleeper-7b48cbb58f-mwhfb                         0/1 nodes are available: 1 Insufficient cpu. no new claims to deallocate, preemption: 0/1 nodes are available: 1 No preemption victims found for incoming pod.
bench-web            53s         Warning   FailedScheduling          pod/web-sleeper-7b48cbb58f-mctxp                         0/1 nodes are available: 1 Insufficient cpu. no new claims to deallocate, preemption: 0/1 nodes are available: 1 No preemption victims found for incoming pod.
bench-web            53s         Warning   FailedScheduling          pod/web-sleeper-7b48cbb58f-m65sv                         0/1 nodes are available: 1 Insufficient cpu. no new claims to deallocate, preemption: 0/1 nodes are available: 1 No preemption victims found for incoming pod.
bench-web            53s         Warning   FailedScheduling          pod/web-sleeper-7b48cbb58f-lmj86                         0/1 nodes are available: 1 Insufficient cpu. no new claims to deallocate, preemption: 0/1 nodes are available: 1 No preemption victims found for incoming pod.
bench-web            53s         Warning   FailedScheduling          pod/web-sleeper-7b48cbb58f-k87pr                         0/1 nodes are available: 1 Insufficient cpu. no new claims to deallocate, preemption: 0/1 nodes are available: 1 No preemption victims found for incoming pod.
bench-web            53s         Warning   FailedScheduling          pod/web-sleeper-7b48cbb58f-jcsw6                         0/1 nodes are available: 1 Insufficient cpu. no new claims to deallocate, preemption: 0/1 nodes are available: 1 No preemption victims found for incoming pod.
bench-web            53s         Warning   FailedScheduling          pod/web-sleeper-7b48cbb58f-j97tz                         0/1 nodes are available: 1 Insufficient cpu. no new claims to deallocate, preemption: 0/1 nodes are available: 1 No preemption victims found for incoming pod.
bench-web            53s         Warning   FailedScheduling          pod/web-sleeper-7b48cbb58f-j7v8z                         0/1 nodes are available: 1 Insufficient cpu. no new claims to deallocate, preemption: 0/1 nodes are available: 1 No preemption victims found for incoming pod.
bench-web            53s         Warning   FailedScheduling          pod/web-sleeper-7b48cbb58f-j4pbs                         0/1 nodes are available: 1 Insufficient cpu. no new claims to deallocate, preemption: 0/1 nodes are available: 1 No preemption victims found for incoming pod.
bench-web            53s         Warning   FailedScheduling          pod/web-sleeper-7b48cbb58f-hf9b5                         0/1 nodes are available: 1 Insufficient cpu. no new claims to deallocate, preemption: 0/1 nodes are available: 1 No preemption victims found for incoming pod.
bench-web            53s         Warning   FailedScheduling          pod/web-sleeper-7b48cbb58f-hdqx5                         0/1 nodes are available: 1 Insufficient cpu. no new claims to deallocate, preemption: 0/1 nodes are available: 1 No preemption victims found for incoming pod.
bench-web            53s         Warning   FailedScheduling          pod/web-sleeper-7b48cbb58f-fswpd                         0/1 nodes are available: 1 Insufficient cpu. no new claims to deallocate, preemption: 0/1 nodes are available: 1 No preemption victims found for incoming pod.
bench-web            53s         Warning   FailedScheduling          pod/web-sleeper-7b48cbb58f-fs26h                         0/1 nodes are available: 1 Insufficient cpu. no new claims to deallocate, preemption: 0/1 nodes are available: 1 No preemption victims found for incoming pod.
bench-web            53s         Warning   FailedScheduling          pod/web-sleeper-7b48cbb58f-fjxbd                         0/1 nodes are available: 1 Insufficient cpu. no new claims to deallocate, preemption: 0/1 nodes are available: 1 No preemption victims found for incoming pod.
bench-web            53s         Warning   FailedScheduling          pod/web-sleeper-7b48cbb58f-fjd2n                         0/1 nodes are available: 1 Insufficient cpu. no new claims to deallocate, preemption: 0/1 nodes are available: 1 No preemption victims found for incoming pod.
bench-web            53s         Warning   FailedScheduling          pod/web-sleeper-7b48cbb58f-fhjkq                         0/1 nodes are available: 1 Insufficient cpu. no new claims to deallocate, preemption: 0/1 nodes are available: 1 No preemption victims found for incoming pod.
bench-web            53s         Warning   FailedScheduling          pod/web-sleeper-7b48cbb58f-f9v4d                         0/1 nodes are available: 1 Insufficient cpu. no new claims to deallocate, preemption: 0/1 nodes are available: 1 No preemption victims found for incoming pod.
bench-web            53s         Warning   FailedScheduling          pod/web-sleeper-7b48cbb58f-ctdb2                         0/1 nodes are available: 1 Insufficient cpu. no new claims to deallocate, preemption: 0/1 nodes are available: 1 No preemption victims found for incoming pod.
bench-web            53s         Warning   FailedScheduling          pod/web-sleeper-7b48cbb58f-c8m29                         0/1 nodes are available: 1 Insufficient cpu. no new claims to deallocate, preemption: 0/1 nodes are available: 1 No preemption victims found for incoming pod.
bench-web            53s         Warning   FailedScheduling          pod/web-sleeper-7b48cbb58f-bbh7w                         0/1 nodes are available: 1 Insufficient cpu. no new claims to deallocate, preemption: 0/1 nodes are available: 1 No preemption victims found for incoming pod.
bench-web            53s         Warning   FailedScheduling          pod/web-sleeper-7b48cbb58f-9wdvf                         0/1 nodes are available: 1 Insufficient cpu. no new claims to deallocate, preemption: 0/1 nodes are available: 1 No preemption victims found for incoming pod.
bench-web            53s         Warning   FailedScheduling          pod/web-sleeper-7b48cbb58f-9pk4p                         0/1 nodes are available: 1 Insufficient cpu. no new claims to deallocate, preemption: 0/1 nodes are available: 1 No preemption victims found for incoming pod.
bench-web            53s         Warning   FailedScheduling          pod/web-sleeper-7b48cbb58f-9ntct                         0/1 nodes are available: 1 Insufficient cpu. no new claims to deallocate, preemption: 0/1 nodes are available: 1 No preemption victims found for incoming pod.
bench-web            53s         Warning   FailedScheduling          pod/web-sleeper-7b48cbb58f-9kvlm                         0/1 nodes are available: 1 Insufficient cpu. no new claims to deallocate, preemption: 0/1 nodes are available: 1 No preemption victims found for incoming pod.
bench-web            53s         Warning   FailedScheduling          pod/web-sleeper-7b48cbb58f-9knzf                         0/1 nodes are available: 1 Insufficient cpu. no new claims to deallocate, preemption: 0/1 nodes are available: 1 No preemption victims found for incoming pod.
bench-web            53s         Warning   FailedScheduling          pod/web-sleeper-7b48cbb58f-9j985                         0/1 nodes are available: 1 Insufficient cpu. no new claims to deallocate, preemption: 0/1 nodes are available: 1 No preemption victims found for incoming pod.
bench-web            53s         Warning   FailedScheduling          pod/web-sleeper-7b48cbb58f-97gjs                         0/1 nodes are available: 1 Insufficient cpu. no new claims to deallocate, preemption: 0/1 nodes are available: 1 No preemption victims found for incoming pod.
bench-web            53s         Warning   FailedScheduling          pod/web-sleeper-7b48cbb58f-8z694                         0/1 nodes are available: 1 Insufficient cpu. no new claims to deallocate, preemption: 0/1 nodes are available: 1 No preemption victims found for incoming pod.
bench-web            53s         Warning   FailedScheduling          pod/web-sleeper-7b48cbb58f-8vmjc                         0/1 nodes are available: 1 Insufficient cpu. no new claims to deallocate, preemption: 0/1 nodes are available: 1 No preemption victims found for incoming pod.
bench-web            53s         Warning   FailedScheduling          pod/web-sleeper-7b48cbb58f-8q64v                         0/1 nodes are available: 1 Insufficient cpu. no new claims to deallocate, preemption: 0/1 nodes are available: 1 No preemption victims found for incoming pod.
bench-web            53s         Warning   FailedScheduling          pod/web-sleeper-7b48cbb58f-8lfs7                         0/1 nodes are available: 1 Insufficient cpu. no new claims to deallocate, preemption: 0/1 nodes are available: 1 No preemption victims found for incoming pod.
bench-web            53s         Warning   FailedScheduling          pod/web-sleeper-7b48cbb58f-8cwzz                         0/1 nodes are available: 1 Insufficient cpu. no new claims to deallocate, preemption: 0/1 nodes are available: 1 No preemption victims found for incoming pod.
bench-web            53s         Warning   FailedScheduling          pod/web-sleeper-7b48cbb58f-88wt5                         0/1 nodes are available: 1 Insufficient cpu. no new claims to deallocate, preemption: 0/1 nodes are available: 1 No preemption victims found for incoming pod.
bench-web            53s         Warning   FailedScheduling          pod/web-sleeper-7b48cbb58f-868gp                         0/1 nodes are available: 1 Insufficient cpu. no new claims to deallocate, preemption: 0/1 nodes are available: 1 No preemption victims found for incoming pod.
bench-web            53s         Warning   FailedScheduling          pod/web-sleeper-7b48cbb58f-7n7bk                         0/1 nodes are available: 1 Insufficient cpu. no new claims to deallocate, preemption: 0/1 nodes are available: 1 No preemption victims found for incoming pod.
bench-web            53s         Warning   FailedScheduling          pod/web-sleeper-7b48cbb58f-7cjbm                         0/1 nodes are available: 1 Insufficient cpu. no new claims to deallocate, preemption: 0/1 nodes are available: 1 No preemption victims found for incoming pod.
bench-web            53s         Warning   FailedScheduling          pod/web-sleeper-7b48cbb58f-6wbll                         0/1 nodes are available: 1 Insufficient cpu. no new claims to deallocate, preemption: 0/1 nodes are available: 1 No preemption victims found for incoming pod.
bench-web            53s         Warning   FailedScheduling          pod/web-sleeper-7b48cbb58f-6vc9g                         0/1 nodes are available: 1 Insufficient cpu. no new claims to deallocate, preemption: 0/1 nodes are available: 1 No preemption victims found for incoming pod.
bench-web            53s         Warning   FailedScheduling          pod/web-sleeper-7b48cbb58f-6ljrm                         0/1 nodes are available: 1 Insufficient cpu. no new claims to deallocate, preemption: 0/1 nodes are available: 1 No preemption victims found for incoming pod.
bench-noisy          53s         Warning   FailedScheduling          pod/crashloop-db7bf9c6b-58j2d                            0/1 nodes are available: 1 Insufficient cpu. no new claims to deallocate, preemption: 0/1 nodes are available: 1 No preemption victims found for incoming pod.
bench-web            53s         Warning   FailedScheduling          pod/web-sleeper-7b48cbb58f-64wch                         0/1 nodes are available: 1 Insufficient cpu. no new claims to deallocate, preemption: 0/1 nodes are available: 1 No preemption victims found for incoming pod.
bench-web            53s         Warning   FailedScheduling          pod/web-sleeper-7b48cbb58f-5svpw                         0/1 nodes are available: 1 Insufficient cpu. no new claims to deallocate, preemption: 0/1 nodes are available: 1 No preemption victims found for incoming pod.
bench-web            53s         Warning   FailedScheduling          pod/web-sleeper-7b48cbb58f-5r9x9                         0/1 nodes are available: 1 Insufficient cpu. no new claims to deallocate, preemption: 0/1 nodes are available: 1 No preemption victims found for incoming pod.
bench-web            53s         Warning   FailedScheduling          pod/web-sleeper-7b48cbb58f-5q8b9                         0/1 nodes are available: 1 Insufficient cpu. no new claims to deallocate, preemption: 0/1 nodes are available: 1 No preemption victims found for incoming pod.
bench-web            53s         Warning   FailedScheduling          pod/web-sleeper-7b48cbb58f-5l649                         0/1 nodes are available: 1 Insufficient cpu. no new claims to deallocate, preemption: 0/1 nodes are available: 1 No preemption victims found for incoming pod.
bench-web            53s         Warning   FailedScheduling          pod/web-sleeper-7b48cbb58f-4cn59                         0/1 nodes are available: 1 Insufficient cpu. no new claims to deallocate, preemption: 0/1 nodes are available: 1 No preemption victims found for incoming pod.
bench-web            53s         Warning   FailedScheduling          pod/web-sleeper-7b48cbb58f-4bshn                         0/1 nodes are available: 1 Insufficient cpu. no new claims to deallocate, preemption: 0/1 nodes are available: 1 No preemption victims found for incoming pod.
bench-web            53s         Warning   FailedScheduling          pod/web-sleeper-7b48cbb58f-47wqv                         0/1 nodes are available: 1 Insufficient cpu. no new claims to deallocate, preemption: 0/1 nodes are available: 1 No preemption victims found for incoming pod.
bench-web            53s         Warning   FailedScheduling          pod/web-sleeper-7b48cbb58f-2x6qm                         0/1 nodes are available: 1 Insufficient cpu. no new claims to deallocate, preemption: 0/1 nodes are available: 1 No preemption victims found for incoming pod.
bench-web            53s         Warning   FailedScheduling          pod/web-sleeper-7b48cbb58f-2lm28                         0/1 nodes are available: 1 Insufficient cpu. no new claims to deallocate, preemption: 0/1 nodes are available: 1 No preemption victims found for incoming pod.
bench-web            53s         Warning   FailedScheduling          pod/web-sleeper-7b48cbb58f-25trq                         0/1 nodes are available: 1 Insufficient cpu. no new claims to deallocate, preemption: 0/1 nodes are available: 1 No preemption victims found for incoming pod.
bench-noisy          53s         Warning   FailedScheduling          pod/crashloop-db7bf9c6b-5vtkn                            0/1 nodes are available: 1 Insufficient cpu. no new claims to deallocate, preemption: 0/1 nodes are available: 1 No preemption victims found for incoming pod.
bench-noisy          53s         Warning   FailedScheduling          pod/crashloop-db7bf9c6b-65s5f                            0/1 nodes are available: 1 Insufficient cpu. no new claims to deallocate, preemption: 0/1 nodes are available: 1 No preemption victims found for incoming pod.
bench-payments       53s         Warning   FailedScheduling          pod/ledger-1                                             0/1 nodes are available: 1 Insufficient cpu. no new claims to deallocate, preemption: 0/1 nodes are available: 1 No preemption victims found for incoming pod.
bench-payments       53s         Warning   FailedScheduling          pod/api-sleeper-7467d44dc4-zv7qf                         0/1 nodes are available: 1 Insufficient cpu. no new claims to deallocate, preemption: 0/1 nodes are available: 1 No preemption victims found for incoming pod.
bench-payments       53s         Warning   FailedScheduling          pod/api-sleeper-7467d44dc4-zr9ls                         0/1 nodes are available: 1 Insufficient cpu. no new claims to deallocate, preemption: 0/1 nodes are available: 1 No preemption victims found for incoming pod.
bench-payments       53s         Warning   FailedScheduling          pod/api-sleeper-7467d44dc4-z2gcx                         0/1 nodes are available: 1 Insufficient cpu. no new claims to deallocate, preemption: 0/1 nodes are available: 1 No preemption victims found for incoming pod.
bench-payments       53s         Warning   FailedScheduling          pod/api-sleeper-7467d44dc4-xxfjk                         0/1 nodes are available: 1 Insufficient cpu. no new claims to deallocate, preemption: 0/1 nodes are available: 1 No preemption victims found for incoming pod.
bench-payments       53s         Warning   FailedScheduling          pod/api-sleeper-7467d44dc4-xmt96                         0/1 nodes are available: 1 Insufficient cpu. no new claims to deallocate, preemption: 0/1 nodes are available: 1 No preemption victims found for incoming pod.
bench-payments       53s         Warning   FailedScheduling          pod/api-sleeper-7467d44dc4-xkn2r                         0/1 nodes are available: 1 Insufficient cpu. no new claims to deallocate, preemption: 0/1 nodes are available: 1 No preemption victims found for incoming pod.
bench-payments       53s         Warning   FailedScheduling          pod/api-sleeper-7467d44dc4-wnmvm                         0/1 nodes are available: 1 Insufficient cpu. no new claims to deallocate, preemption: 0/1 nodes are available: 1 No preemption victims found for incoming pod.
bench-payments       53s         Warning   FailedScheduling          pod/api-sleeper-7467d44dc4-wjjmf                         0/1 nodes are available: 1 Insufficient cpu. no new claims to deallocate, preemption: 0/1 nodes are available: 1 No preemption victims found for incoming pod.
bench-payments       53s         Warning   FailedScheduling          pod/api-sleeper-7467d44dc4-wd4lf                         0/1 nodes are available: 1 Insufficient cpu. no new claims to deallocate, preemption: 0/1 nodes are available: 1 No preemption victims found for incoming pod.
bench-payments       53s         Warning   FailedScheduling          pod/api-sleeper-7467d44dc4-wbt6n                         0/1 nodes are available: 1 Insufficient cpu. no new claims to deallocate, preemption: 0/1 nodes are available: 1 No preemption victims found for incoming pod.
bench-payments       53s         Warning   FailedScheduling          pod/api-sleeper-7467d44dc4-w4f2l                         0/1 nodes are available: 1 Insufficient cpu. no new claims to deallocate, preemption: 0/1 nodes are available: 1 No preemption victims found for incoming pod.
bench-payments       53s         Warning   FailedScheduling          pod/api-sleeper-7467d44dc4-w2slx                         0/1 nodes are available: 1 Insufficient cpu. no new claims to deallocate, preemption: 0/1 nodes are available: 1 No preemption victims found for incoming pod.
bench-payments       53s         Warning   FailedScheduling          pod/api-sleeper-7467d44dc4-vj9x7                         0/1 nodes are available: 1 Insufficient cpu. no new claims to deallocate, preemption: 0/1 nodes are available: 1 No preemption victims found for incoming pod.
bench-payments       53s         Warning   FailedScheduling          pod/api-sleeper-7467d44dc4-v2qbt                         0/1 nodes are available: 1 Insufficient cpu. no new claims to deallocate, preemption: 0/1 nodes are available: 1 No preemption victims found for incoming pod.
bench-payments       53s         Warning   FailedScheduling          pod/api-sleeper-7467d44dc4-ttxln                         0/1 nodes are available: 1 Insufficient cpu. no new claims to deallocate, preemption: 0/1 nodes are available: 1 No preemption victims found for incoming pod.
bench-payments       53s         Warning   FailedScheduling          pod/api-sleeper-7467d44dc4-ttp8d                         0/1 nodes are available: 1 Insufficient cpu. no new claims to deallocate, preemption: 0/1 nodes are available: 1 No preemption victims found for incoming pod.
bench-payments       53s         Warning   FailedScheduling          pod/api-sleeper-7467d44dc4-tggz2                         0/1 nodes are available: 1 Insufficient cpu. no new claims to deallocate, preemption: 0/1 nodes are available: 1 No preemption victims found for incoming pod.
bench-payments       53s         Warning   FailedScheduling          pod/api-sleeper-7467d44dc4-t6556                         0/1 nodes are available: 1 Insufficient cpu. no new claims to deallocate, preemption: 0/1 nodes are available: 1 No preemption victims found for incoming pod.
bench-payments       53s         Warning   FailedScheduling          pod/api-sleeper-7467d44dc4-sqx22                         0/1 nodes are available: 1 Insufficient cpu. no new claims to deallocate, preemption: 0/1 nodes are available: 1 No preemption victims found for incoming pod.
bench-payments       53s         Warning   FailedScheduling          pod/api-sleeper-7467d44dc4-s5rzj                         0/1 nodes are available: 1 Insufficient cpu. no new claims to deallocate, preemption: 0/1 nodes are available: 1 No preemption victims found for incoming pod.
bench-payments       53s         Warning   FailedScheduling          pod/api-sleeper-7467d44dc4-rd44p                         0/1 nodes are available: 1 Insufficient cpu. no new claims to deallocate, preemption: 0/1 nodes are available: 1 No preemption victims found for incoming pod.
bench-payments       53s         Warning   FailedScheduling          pod/api-sleeper-7467d44dc4-qpdfc                         0/1 nodes are available: 1 Insufficient cpu. no new claims to deallocate, preemption: 0/1 nodes are available: 1 No preemption victims found for incoming pod.
bench-payments       53s         Warning   FailedScheduling          pod/api-sleeper-7467d44dc4-q7pmb                         0/1 nodes are available: 1 Insufficient cpu. no new claims to deallocate, preemption: 0/1 nodes are available: 1 No preemption victims found for incoming pod.
bench-payments       53s         Warning   FailedScheduling          pod/api-sleeper-7467d44dc4-q6sgd                         0/1 nodes are available: 1 Insufficient cpu. no new claims to deallocate, preemption: 0/1 nodes are available: 1 No preemption victims found for incoming pod.
bench-payments       53s         Warning   FailedScheduling          pod/api-sleeper-7467d44dc4-q4d9g                         0/1 nodes are available: 1 Insufficient cpu. no new claims to deallocate, preemption: 0/1 nodes are available: 1 No preemption victims found for incoming pod.
bench-web            53s         Warning   FailedScheduling          pod/web-sleeper-7b48cbb58f-snpql                         0/1 nodes are available: 1 Insufficient cpu. no new claims to deallocate, preemption: 0/1 nodes are available: 1 No preemption victims found for incoming pod.
bench-payments       53s         Warning   FailedScheduling          pod/api-sleeper-7467d44dc4-pflb2                         0/1 nodes are available: 1 Insufficient cpu. no new claims to deallocate, preemption: 0/1 nodes are available: 1 No preemption victims found for incoming pod.
bench-payments       53s         Warning   FailedScheduling          pod/api-sleeper-7467d44dc4-p9lzk                         0/1 nodes are available: 1 Insufficient cpu. no new claims to deallocate, preemption: 0/1 nodes are available: 1 No preemption victims found for incoming pod.
bench-payments       53s         Warning   FailedScheduling          pod/api-sleeper-7467d44dc4-lsl9f                         0/1 nodes are available: 1 Insufficient cpu. no new claims to deallocate, preemption: 0/1 nodes are available: 1 No preemption victims found for incoming pod.
monitoring           53s         Warning   FailedScheduling          pod/prometheus-fake-7ccfb864b6-45sp2                     0/1 nodes are available: 1 Insufficient cpu, 1 Insufficient memory. no new claims to deallocate, preemption: 0/1 nodes are available: 1 No preemption victims found for incoming pod.
bench-noisy          53s         Warning   FailedScheduling          pod/crashloop-db7bf9c6b-7tjp8                            0/1 nodes are available: 1 Insufficient cpu. no new claims to deallocate, preemption: 0/1 nodes are available: 1 No preemption victims found for incoming pod.
bench-noisy          53s         Warning   FailedScheduling          pod/crashloop-db7bf9c6b-8fjsm                            0/1 nodes are available: 1 Insufficient cpu. no new claims to deallocate, preemption: 0/1 nodes are available: 1 No preemption victims found for incoming pod.
bench-noisy          53s         Warning   FailedScheduling          pod/crashloop-db7bf9c6b-b95z8                            0/1 nodes are available: 1 Insufficient cpu. no new claims to deallocate, preemption: 0/1 nodes are available: 1 No preemption victims found for incoming pod.
bench-payments       53s         Warning   FailedScheduling          pod/api-sleeper-7467d44dc4-lmrwm                         0/1 nodes are available: 1 Insufficient cpu. no new claims to deallocate, preemption: 0/1 nodes are available: 1 No preemption victims found for incoming pod.
bench-payments       53s         Warning   FailedScheduling          pod/api-sleeper-7467d44dc4-llxqx                         0/1 nodes are available: 1 Insufficient cpu. no new claims to deallocate, preemption: 0/1 nodes are available: 1 No preemption victims found for incoming pod.
bench-noisy          53s         Warning   FailedScheduling          pod/crashloop-db7bf9c6b-bsgg5                            0/1 nodes are available: 1 Insufficient cpu. no new claims to deallocate, preemption: 0/1 nodes are available: 1 No preemption victims found for incoming pod.
bench-noisy          53s         Warning   FailedScheduling          pod/crashloop-db7bf9c6b-ccqm4                            0/1 nodes are available: 1 Insufficient cpu. no new claims to deallocate, preemption: 0/1 nodes are available: 1 No preemption victims found for incoming pod.
bench-noisy          53s         Warning   FailedScheduling          pod/crashloop-db7bf9c6b-gdkc8                            0/1 nodes are available: 1 Insufficient cpu. no new claims to deallocate, preemption: 0/1 nodes are available: 1 No preemption victims found for incoming pod.
bench-noisy          53s         Warning   FailedScheduling          pod/crashloop-db7bf9c6b-kl4lh                            0/1 nodes are available: 1 Insufficient cpu. no new claims to deallocate, preemption: 0/1 nodes are available: 1 No preemption victims found for incoming pod.
bench-payments       53s         Warning   FailedScheduling          pod/api-sleeper-7467d44dc4-l6jds                         0/1 nodes are available: 1 Insufficient cpu. no new claims to deallocate, preemption: 0/1 nodes are available: 1 No preemption victims found for incoming pod.
bench-payments       53s         Warning   FailedScheduling          pod/api-sleeper-7467d44dc4-l6575                         0/1 nodes are available: 1 Insufficient cpu. no new claims to deallocate, preemption: 0/1 nodes are available: 1 No preemption victims found for incoming pod.
bench-noisy          53s         Warning   FailedScheduling          pod/crashloop-db7bf9c6b-kslqn                            0/1 nodes are available: 1 Insufficient cpu. no new claims to deallocate, preemption: 0/1 nodes are available: 1 No preemption victims found for incoming pod.
payments             53s         Warning   FailedScheduling          pod/redis-69b984c64-n2knp                                0/1 nodes are available: 1 Insufficient cpu, 1 Insufficient memory. no new claims to deallocate, preemption: 0/1 nodes are available: 1 No preemption victims found for incoming pod.
bench-noisy          53s         Warning   FailedScheduling          pod/crashloop-db7bf9c6b-kzlqn                            0/1 nodes are available: 1 Insufficient cpu. no new claims to deallocate, preemption: 0/1 nodes are available: 1 No preemption victims found for incoming pod.
bench-noisy          53s         Warning   FailedScheduling          pod/crashloop-db7bf9c6b-n79hm                            0/1 nodes are available: 1 Insufficient cpu. no new claims to deallocate, preemption: 0/1 nodes are available: 1 No preemption victims found for incoming pod.
bench-payments       53s         Warning   FailedScheduling          pod/api-sleeper-7467d44dc4-kl2mk                         0/1 nodes are available: 1 Insufficient cpu. no new claims to deallocate, preemption: 0/1 nodes are available: 1 No preemption victims found for incoming pod.
bench-payments       53s         Warning   FailedScheduling          pod/api-sleeper-7467d44dc4-jls9d                         0/1 nodes are available: 1 Insufficient cpu. no new claims to deallocate, preemption: 0/1 nodes are available: 1 No preemption victims found for incoming pod.
bench-payments       53s         Warning   FailedScheduling          pod/api-sleeper-7467d44dc4-jbmr5                         0/1 nodes are available: 1 Insufficient cpu. no new claims to deallocate, preemption: 0/1 nodes are available: 1 No preemption victims found for incoming pod.
bench-payments       53s         Warning   FailedScheduling          pod/api-sleeper-7467d44dc4-hhglc                         0/1 nodes are available: 1 Insufficient cpu. no new claims to deallocate, preemption: 0/1 nodes are available: 1 No preemption victims found for incoming pod.
payments             53s         Warning   FailedScheduling          pod/redis-69b984c64-qgt5n                                0/1 nodes are available: 1 Insufficient cpu, 1 Insufficient memory. no new claims to deallocate, preemption: 0/1 nodes are available: 1 No preemption victims found for incoming pod.
bench-payments       53s         Warning   FailedScheduling          pod/api-sleeper-7467d44dc4-flxsd                         0/1 nodes are available: 1 Insufficient cpu. no new claims to deallocate, preemption: 0/1 nodes are available: 1 No preemption victims found for incoming pod.
bench-payments       53s         Warning   FailedScheduling          pod/api-sleeper-7467d44dc4-fct4c                         0/1 nodes are available: 1 Insufficient cpu. no new claims to deallocate, preemption: 0/1 nodes are available: 1 No preemption victims found for incoming pod.
bench-payments       53s         Warning   FailedScheduling          pod/api-sleeper-7467d44dc4-dmz48                         0/1 nodes are available: 1 Insufficient cpu. no new claims to deallocate, preemption: 0/1 nodes are available: 1 No preemption victims found for incoming pod.
bench-payments       53s         Warning   FailedScheduling          pod/api-sleeper-7467d44dc4-czhjp                         0/1 nodes are available: 1 Insufficient cpu. no new claims to deallocate, preemption: 0/1 nodes are available: 1 No preemption victims found for incoming pod.
bench-noisy          53s         Warning   FailedScheduling          pod/crashloop-db7bf9c6b-q2jjw                            0/1 nodes are available: 1 Insufficient cpu. no new claims to deallocate, preemption: 0/1 nodes are available: 1 No preemption victims found for incoming pod.
bench-payments       53s         Normal    Created                   pod/api-sleeper-7467d44dc4-cxhtk                         Container created
bench-payments       53s         Normal    Pulled                    pod/api-sleeper-7467d44dc4-cxhtk                         Successfully pulled image "busybox:1.36" in 785ms (42.781s including waiting). Image size: 1906887 bytes.
bench-payments       53s         Warning   FailedScheduling          pod/api-sleeper-7467d44dc4-bn57f                         0/1 nodes are available: 1 Insufficient cpu. no new claims to deallocate, preemption: 0/1 nodes are available: 1 No preemption victims found for incoming pod.
bench-payments       53s         Warning   FailedScheduling          pod/api-sleeper-7467d44dc4-bbn5q                         0/1 nodes are available: 1 Insufficient cpu. no new claims to deallocate, preemption: 0/1 nodes are available: 1 No preemption victims found for incoming pod.
bench-payments       53s         Warning   FailedScheduling          pod/api-sleeper-7467d44dc4-b9csc                         0/1 nodes are available: 1 Insufficient cpu. no new claims to deallocate, preemption: 0/1 nodes are available: 1 No preemption victims found for incoming pod.
bench-payments       53s         Warning   FailedScheduling          pod/api-sleeper-7467d44dc4-b6zql                         0/1 nodes are available: 1 Insufficient cpu. no new claims to deallocate, preemption: 0/1 nodes are available: 1 No preemption victims found for incoming pod.
bench-payments       53s         Warning   FailedScheduling          pod/api-sleeper-7467d44dc4-b6tfg                         0/1 nodes are available: 1 Insufficient cpu. no new claims to deallocate, preemption: 0/1 nodes are available: 1 No preemption victims found for incoming pod.
bench-payments       53s         Warning   FailedScheduling          pod/api-sleeper-7467d44dc4-b59d7                         0/1 nodes are available: 1 Insufficient cpu. no new claims to deallocate, preemption: 0/1 nodes are available: 1 No preemption victims found for incoming pod.
bench-payments       53s         Warning   FailedScheduling          pod/api-sleeper-7467d44dc4-b4g4r                         0/1 nodes are available: 1 Insufficient cpu. no new claims to deallocate, preemption: 0/1 nodes are available: 1 No preemption victims found for incoming pod.
bench-payments       53s         Warning   FailedScheduling          pod/api-sleeper-7467d44dc4-9ttcl                         0/1 nodes are available: 1 Insufficient cpu. no new claims to deallocate, preemption: 0/1 nodes are available: 1 No preemption victims found for incoming pod.
bench-payments       53s         Warning   FailedScheduling          pod/api-sleeper-7467d44dc4-9npk8                         0/1 nodes are available: 1 Insufficient cpu. no new claims to deallocate, preemption: 0/1 nodes are available: 1 No preemption victims found for incoming pod.
bench-payments       53s         Warning   FailedScheduling          pod/api-sleeper-7467d44dc4-9k4rz                         0/1 nodes are available: 1 Insufficient cpu. no new claims to deallocate, preemption: 0/1 nodes are available: 1 No preemption victims found for incoming pod.
bench-payments       53s         Warning   FailedScheduling          pod/api-sleeper-7467d44dc4-89fxr                         0/1 nodes are available: 1 Insufficient cpu. no new claims to deallocate, preemption: 0/1 nodes are available: 1 No preemption victims found for incoming pod.
bench-payments       53s         Warning   FailedScheduling          pod/api-sleeper-7467d44dc4-7wq2k                         0/1 nodes are available: 1 Insufficient cpu. no new claims to deallocate, preemption: 0/1 nodes are available: 1 No preemption victims found for incoming pod.
bench-payments       53s         Warning   FailedScheduling          pod/api-sleeper-7467d44dc4-7qd5w                         0/1 nodes are available: 1 Insufficient cpu. no new claims to deallocate, preemption: 0/1 nodes are available: 1 No preemption victims found for incoming pod.
bench-payments       53s         Warning   FailedScheduling          pod/api-sleeper-7467d44dc4-7d42s                         0/1 nodes are available: 1 Insufficient cpu. no new claims to deallocate, preemption: 0/1 nodes are available: 1 No preemption victims found for incoming pod.
bench-payments       53s         Warning   FailedScheduling          pod/api-sleeper-7467d44dc4-6bb6x                         0/1 nodes are available: 1 Insufficient cpu. no new claims to deallocate, preemption: 0/1 nodes are available: 1 No preemption victims found for incoming pod.
bench-payments       53s         Warning   FailedScheduling          pod/api-sleeper-7467d44dc4-5lxkt                         0/1 nodes are available: 1 Insufficient cpu. no new claims to deallocate, preemption: 0/1 nodes are available: 1 No preemption victims found for incoming pod.
bench-payments       53s         Warning   FailedScheduling          pod/api-sleeper-7467d44dc4-5cbcl                         0/1 nodes are available: 1 Insufficient cpu. no new claims to deallocate, preemption: 0/1 nodes are available: 1 No preemption victims found for incoming pod.
bench-noisy          53s         Warning   FailedScheduling          pod/crashloop-db7bf9c6b-q4gn9                            0/1 nodes are available: 1 Insufficient cpu. no new claims to deallocate, preemption: 0/1 nodes are available: 1 No preemption victims found for incoming pod.
bench-noisy          53s         Warning   FailedScheduling          pod/crashloop-db7bf9c6b-q77q5                            0/1 nodes are available: 1 Insufficient cpu. no new claims to deallocate, preemption: 0/1 nodes are available: 1 No preemption victims found for incoming pod.
bench-noisy          53s         Warning   FailedScheduling          pod/crashloop-db7bf9c6b-qf6gg                            0/1 nodes are available: 1 Insufficient cpu. no new claims to deallocate, preemption: 0/1 nodes are available: 1 No preemption victims found for incoming pod.
bench-payments       53s         Warning   FailedScheduling          pod/api-sleeper-7467d44dc4-55b4r                         0/1 nodes are available: 1 Insufficient cpu. no new claims to deallocate, preemption: 0/1 nodes are available: 1 No preemption victims found for incoming pod.
bench-payments       53s         Warning   FailedScheduling          pod/api-sleeper-7467d44dc4-4lxd4                         0/1 nodes are available: 1 Insufficient cpu. no new claims to deallocate, preemption: 0/1 nodes are available: 1 No preemption victims found for incoming pod.
bench-payments       53s         Normal    Started                   pod/api-sleeper-7467d44dc4-4ds98                         Container started
bench-payments       53s         Warning   FailedScheduling          pod/api-sleeper-7467d44dc4-49xzg                         0/1 nodes are available: 1 Insufficient cpu. no new claims to deallocate, preemption: 0/1 nodes are available: 1 No preemption victims found for incoming pod.
bench-payments       53s         Warning   FailedScheduling          pod/api-sleeper-7467d44dc4-2kf69                         0/1 nodes are available: 1 Insufficient cpu. no new claims to deallocate, preemption: 0/1 nodes are available: 1 No preemption victims found for incoming pod.
bench-noisy          53s         Warning   FailedScheduling          pod/crashloop-db7bf9c6b-zbhbz                            0/1 nodes are available: 1 Insufficient cpu. no new claims to deallocate, preemption: 0/1 nodes are available: 1 No preemption victims found for incoming pod.
bench-noisy          53s         Warning   FailedScheduling          pod/crashloop-db7bf9c6b-wcct5                            0/1 nodes are available: 1 Insufficient cpu. no new claims to deallocate, preemption: 0/1 nodes are available: 1 No preemption victims found for incoming pod.
bench-noisy          53s         Warning   FailedScheduling          pod/crashloop-db7bf9c6b-w94c6                            0/1 nodes are available: 1 Insufficient cpu. no new claims to deallocate, preemption: 0/1 nodes are available: 1 No preemption victims found for incoming pod.
bench-noisy          53s         Warning   FailedScheduling          pod/crashloop-db7bf9c6b-w74r4                            0/1 nodes are available: 1 Insufficient cpu. no new claims to deallocate, preemption: 0/1 nodes are available: 1 No preemption victims found for incoming pod.
bench-noisy          53s         Warning   FailedScheduling          pod/crashloop-db7bf9c6b-w4x4g                            0/1 nodes are available: 1 Insufficient cpu. no new claims to deallocate, preemption: 0/1 nodes are available: 1 No preemption victims found for incoming pod.
bench-noisy          53s         Warning   FailedScheduling          pod/crashloop-db7bf9c6b-vz7x9                            0/1 nodes are available: 1 Insufficient cpu. no new claims to deallocate, preemption: 0/1 nodes are available: 1 No preemption victims found for incoming pod.
bench-noisy          53s         Warning   FailedScheduling          pod/crashloop-db7bf9c6b-txz2t                            0/1 nodes are available: 1 Insufficient cpu. no new claims to deallocate, preemption: 0/1 nodes are available: 1 No preemption victims found for incoming pod.
bench-noisy          53s         Warning   FailedScheduling          pod/crashloop-db7bf9c6b-trwx6                            0/1 nodes are available: 1 Insufficient cpu. no new claims to deallocate, preemption: 0/1 nodes are available: 1 No preemption victims found for incoming pod.
bench-noisy          53s         Warning   FailedScheduling          pod/crashloop-db7bf9c6b-tqb95                            0/1 nodes are available: 1 Insufficient cpu. no new claims to deallocate, preemption: 0/1 nodes are available: 1 No preemption victims found for incoming pod.
bench-noisy          53s         Warning   FailedScheduling          pod/crashloop-db7bf9c6b-rn5wt                            0/1 nodes are available: 1 Insufficient cpu. no new claims to deallocate, preemption: 0/1 nodes are available: 1 No preemption victims found for incoming pod.
bench-noisy          53s         Warning   FailedScheduling          pod/crashloop-db7bf9c6b-rjg5g                            0/1 nodes are available: 1 Insufficient cpu. no new claims to deallocate, preemption: 0/1 nodes are available: 1 No preemption victims found for incoming pod.
bench-noisy          53s         Warning   FailedScheduling          pod/crashloop-db7bf9c6b-r9277                            0/1 nodes are available: 1 Insufficient cpu. no new claims to deallocate, preemption: 0/1 nodes are available: 1 No preemption victims found for incoming pod.
bench-platform       52s         Normal    Completed                 job/scheduled-report-29715585                            Job completed
bench-payments       52s         Normal    Pulled                    pod/api-sleeper-7467d44dc4-lps4c                         Successfully pulled image "busybox:1.36" in 732ms (43.432s including waiting). Image size: 1906887 bytes.
bench-payments       52s         Normal    Created                   pod/api-sleeper-7467d44dc4-lps4c                         Container created
bench-payments       52s         Normal    Started                   pod/api-sleeper-7467d44dc4-cxhtk                         Container started
bench-platform       52s         Normal    SawCompletedJob           cronjob/scheduled-report                                 Saw completed job: scheduled-report-29715585, condition: Complete
bench-payments       51s         Normal    Started                   pod/api-sleeper-7467d44dc4-kmvv5                         Container started
bench-payments       51s         Normal    Started                   pod/api-sleeper-7467d44dc4-lps4c                         Container started
bench-payments       51s         Normal    Pulled                    pod/api-sleeper-7467d44dc4-kmvv5                         Successfully pulled image "busybox:1.36" in 725ms (44.155s including waiting). Image size: 1906887 bytes.
bench-payments       51s         Normal    Created                   pod/api-sleeper-7467d44dc4-kmvv5                         Container created
bench-payments       51s         Normal    Created                   pod/api-sleeper-7467d44dc4-55pvq                         Container created
bench-payments       51s         Normal    Pulled                    pod/api-sleeper-7467d44dc4-55pvq                         Successfully pulled image "busybox:1.36" in 743ms (42.617s including waiting). Image size: 1906887 bytes.
bench-payments       50s         Normal    Started                   pod/api-sleeper-7467d44dc4-55pvq                         Container started
payments             36s         Normal    Pulled                    pod/crashloop-ccf4f7c64-4mgwp                            Container image "busybox:1.36" already present on machine and can be accessed by the pod
payments             36s         Normal    Started                   pod/crashloop-ccf4f7c64-4mgwp                            Container started
payments             36s         Normal    Created                   pod/crashloop-ccf4f7c64-4mgwp                            Container created
payments             35s         Warning   BackOff                   pod/crashloop-ccf4f7c64-4mgwp                            Back-off restarting failed container bad in pod crashloop-ccf4f7c64-4mgwp_payments(be97d63b-c0cf-45a9-bbc6-a7acd7f6f181)
bench-noisy          30s         Normal    Created                   pod/crashloop-db7bf9c6b-92c2b                            Container created
bench-noisy          30s         Normal    Started                   pod/crashloop-db7bf9c6b-92c2b                            Container started
bench-noisy          30s         Normal    Pulled                    pod/crashloop-db7bf9c6b-92c2b                            Container image "busybox:1.36" already present on machine and can be accessed by the pod
bench-noisy          29s         Warning   BackOff                   pod/crashloop-db7bf9c6b-92c2b                            Back-off restarting failed container bad in pod crashloop-db7bf9c6b-92c2b_bench-noisy(627e768a-3933-4298-a611-2217c952e4a2)
bench-noisy          27s         Normal    Created                   pod/crashloop-db7bf9c6b-cdnxz                            Container created
bench-noisy          27s         Normal    Started                   pod/crashloop-db7bf9c6b-cdnxz                            Container started
bench-noisy          27s         Normal    Pulled                    pod/crashloop-db7bf9c6b-cdnxz                            Container image "busybox:1.36" already present on machine and can be accessed by the pod
bench-noisy          26s         Warning   BackOff                   pod/crashloop-db7bf9c6b-cdnxz                            Back-off restarting failed container bad in pod crashloop-db7bf9c6b-cdnxz_bench-noisy(e19b0363-9add-496a-90d2-a2057a82bdc2)
bench-noisy          21s         Normal    Pulled                    pod/crashloop-db7bf9c6b-8kntx                            Container image "busybox:1.36" already present on machine and can be accessed by the pod
bench-noisy          21s         Normal    Started                   pod/crashloop-db7bf9c6b-8kntx                            Container started
bench-noisy          21s         Normal    Created                   pod/crashloop-db7bf9c6b-8kntx                            Container created
bench-noisy          20s         Warning   BackOff                   pod/crashloop-db7bf9c6b-8kntx                            Back-off restarting failed container bad in pod crashloop-db7bf9c6b-8kntx_bench-noisy(138db48c-8631-4dc4-af80-9e7afeddacd5)
bench-noisy          20s         Normal    Created                   pod/crashloop-db7bf9c6b-pkg9l                            Container created
bench-noisy          20s         Normal    Started                   pod/crashloop-db7bf9c6b-pkg9l                            Container started
bench-noisy          20s         Normal    Pulled                    pod/crashloop-db7bf9c6b-pkg9l                            Container image "busybox:1.36" already present on machine and can be accessed by the pod
bench-noisy          19s         Warning   BackOff                   pod/crashloop-db7bf9c6b-pkg9l                            Back-off restarting failed container bad in pod crashloop-db7bf9c6b-pkg9l_bench-noisy(4b1b173a-12d7-4a40-9d82-18a7bee2da94)
